Workbook
Name \a: [1]Pago!#REF!
Name \a: [1]Pago!#REF!
Name \a: [1]Pago!#REF!
Name \a: [1]Pago!#REF!
Name \n: [1]Pago!#REF!
Name \n: [1]Pago!#REF!
Name \n: [1]Pago!#REF!
Name \n: [1]Pago!#REF!
Name _a: [2]Proceso!#REF!
Name _a: [3]Proceso!#REF!
Name _a: [2]Proceso!#REF!
Name _a: [2]Proceso!#REF!
Name INVLINS: [2]Proceso!#REF!
Name INVLINS: [2]Proceso!#REF!
Name INVLINS: [3]Proceso!#REF!
Name INVLINS: [2]Proceso!#REF!
Name INVLINS: [2]Proceso!#REF!
Name INVMAGN: [2]Proceso!#REF!
Name INVMAGN: [3]Proceso!#REF!
Name INVMAGN: [2]Proceso!#REF!
Name INVMAGN: [2]Proceso!#REF!
Name INVMOL1: [2]Proceso!#REF!
Name INVMOL1: [3]Proceso!#REF!
Name INVMOL1: [2]Proceso!#REF!
Name INVMOL1: [2]Proceso!#REF!
Name INVPERF: [2]Proceso!#REF!
Name INVPERF: [3]Proceso!#REF!
Name INVPERF: [2]Proceso!#REF!
Name INVPERF: [2]Proceso!#REF!
Name INVPLAS: [2]Proceso!#REF!
Name INVPLAS: [3]Proceso!#REF!
Name INVPLAS: [2]Proceso!#REF!
Name INVPLAS: [2]Proceso!#REF!
Name INVPLESSY: [2]Proceso!#REF!
Name INVPLESSY: [3]Proceso!#REF!
Name INVPLESSY: [2]Proceso!#REF!
Name INVPLESSY: [2]Proceso!#REF!
Name INVSELLO: [2]Proceso!#REF!
Name INVSELLO: [3]Proceso!#REF!
Name INVSELLO: [2]Proceso!#REF!
Name INVSELLO: [2]Proceso!#REF!
Name INVYOD: [2]Proceso!#REF!
Name INVYOD: [3]Proceso!#REF!
Name INVYOD: [2]Proceso!#REF!
Name INVYOD: [2]Proceso!#REF!
Name Macro1: [4]Macros!$A$1
Name Macro1: [5]Macros!$A$1
Name Macro2: [6]Macro!$A$1
Name Macro2: [7]Macro!$A$1
Name MENSUAL: '[8]Calculadora ISR 2023'!$P$42:$S$54
Name MESES: #REF!
Name MESES: #REF!
Name MESES: #REF!
Name MESES: #REF!
Name MESES: #REF!
Name NOMBRE: #REF!
Name NOMBRE: #REF!
Name NOMBRE: #REF!
Name NOMBRE: #REF!
Name QUINCENAL: '[8]Calculadora ISR 2023'!$K$42:$N$54

Sheet LUXIMIA 
B2: CONSTRUCTORA LUXIMIA S.A DE C.V.
A10: GRUPO LUXIMIA
A11: 02. DEL 16-31 ENERO 2025 | E11: SUELDO BRUTO | Y11: FACTURACION
L12: TOTAL PERCEPCIONES | R12: NETO | Z12: 0.03
A13: CÓDIGO | B13: NOMBRE | C13: DEPTO | D13: PUESTO | E13: NETO MENSUAL | F13: SDO | G13: DIAS | H13: SUELDO | I13: PRIMA VACACIONAL | J13: RETROACTIVO | K13: SUBSIDIO | M13: ISR | N13: IMSS | O13: PRESTAMO | P13: INFONAVIT | Q13: TOTAL DEDUCCIONES | T13: ISN | U13: PREVIO COSTO SOCIAL | V13: TOTAL CARGA SOCIAL | W13: TOTAL NOMINA | Y13: NOMINAS Y COSTOS TRIBUTARIO | Z13: COMISION | AA13: SUB-TOTAL | AB13: IVA | AC13: TOTAL FACTURACION
AB14: 0.16
R15: YUKAWA
A16: 1 | B16: BUSTOS MOLINA GERARDO | C16: CONTABILIDAD | D16: CONTADOR FINANCIERO | E16: =+F16*30 -> 14935.8 | F16: 497.86 | G16: 16 | H16: =F16*G16 -> 7965.76 | L16: =SUM(H16:K16) -> 7965.76 | M16: 878.42 | N16: 211.1 | O16: 0 | P16: 1952.49 | Q16: =SUM(M16:P16) -> 3042.01 | R16: =+L16-Q16 -> 4923.75 | T16: 318.6304 | U16: 2244.01 | V16: =+U16+T16 -> 2562.6404 | W16: =+L16 -> 7965.76 | Y16: =+W16+V16 -> 10528.4 | Z16: =+Y16*$Z$12 -> 315.85201 | AA16: =+Y16+Z16 -> 10844.252 | AB16: =+AA16*$AB$14 -> 1735.0804 | AC16: =+AA16+AB16 -> 12579.333
A17: 2 | B17: CASAS CORTES JOSE ANDRES | C17: CONTABILIDAD | D17: CUENTAS POR PAGAR | E17: =+F17*30 -> 14935.8 | F17: 497.86 | G17: 16 | H17: =F17*G17 -> 7965.76 | K17: 0 | L17: =SUM(H17:K17) -> 7965.76 | M17: 878.42 | N17: 211.1 | O17: 0 | P17: 0 | Q17: =SUM(M17:P17) -> 1089.52 | R17: =+L17-Q17 -> 6876.24 | T17: 318.6304 | U17: 2244.01 | V17: =+U17+T17 -> 2562.6404 | W17: =+L17 -> 7965.76 | Y17: =+W17+V17 -> 10528.4 | Z17: =+Y17*$Z$12 -> 315.85201 | AA17: =+Y17+Z17 -> 10844.252 | AB17: =+AA17*$AB$14 -> 1735.0804 | AC17: =+AA17+AB17 -> 12579.333
A18: 3 | B18: DOMINGUEZ CHIM CESAR MANUEL | C18: DIRECCION CONSEJO | D18: MARINERO | E18: =+F18*30 -> 14935.8 | F18: 497.86 | G18: 16 | H18: =F18*G18 -> 7965.76 | K18: 0 | L18: =SUM(H18:K18) -> 7965.76 | M18: 878.42 | N18: 211.1 | O18: 0 | P18: 1311.95 | Q18: =SUM(M18:P18) -> 2401.47 | R18: =+L18-Q18 -> 5564.29 | T18: 318.6304 | U18: 2244.01 | V18: =+U18+T18 -> 2562.6404 | W18: =+L18 -> 7965.76 | Y18: =+W18+V18 -> 10528.4 | Z18: =+Y18*$Z$12 -> 315.85201 | AA18: =+Y18+Z18 -> 10844.252 | AB18: =+AA18*$AB$14 -> 1735.0804 | AC18: =+AA18+AB18 -> 12579.333
A19: 4 | B19: GALEANA MARIN EDWIN | C19: SISTEMAS | D19: JEFE DE SISTEMAS | E19: =+F19*30 -> 22403.7 | F19: 746.79 | G19: 16 | H19: =F19*G19 -> 11948.64 | K19: 0 | L19: =SUM(H19:K19) -> 11948.64 | M19: 1729.17 | N19: 327.08 | O19: 0 | P19: 0 | Q19: =SUM(M19:P19) -> 2056.25 | R19: =+L19-Q19 -> 9892.39 | T19: 477.9456 | U19: 3177.71 | V19: =+U19+T19 -> 3655.6556 | W19: =+L19 -> 11948.64 | Y19: =+W19+V19 -> 15604.296 | Z19: =+Y19*$Z$12 -> 468.12887 | AA19: =+Y19+Z19 -> 16072.424 | AB19: =+AA19*$AB$14 -> 2571.5879 | AC19: =+AA19+AB19 -> 18644.012
A20: 5 | B20: GUTIERREZ CASTILLO FAYNE DAFNE | C20: JURIDICO | D20: ENCARGADO JURIDICO | E20: =+F20*30 -> 14935.8 | F20: 497.86 | G20: 16 | H20: =F20*G20 -> 7965.76 | K20: 0 | L20: =SUM(H20:K20) -> 7965.76 | M20: 878.42 | N20: 211.1 | O20: 0 | P20: 1458.86 | Q20: =SUM(M20:P20) -> 2548.38 | R20: =+L20-Q20 -> 5417.38 | T20: 318.6304 | U20: 2244.01 | V20: =+U20+T20 -> 2562.6404 | W20: =+L20 -> 7965.76 | Y20: =+W20+V20 -> 10528.4 | Z20: =+Y20*$Z$12 -> 315.85201 | AA20: =+Y20+Z20 -> 10844.252 | AB20: =+AA20*$AB$14 -> 1735.0804 | AC20: =+AA20+AB20 -> 12579.333
A21: 6 | B21: HERNANDEZ DZUL JUAN RAMON | C21: SEGURIDAD | D21: TRASLADO DE VALORES | E21: =+F21*30 -> 14935.8 | F21: 497.86 | G21: 16 | H21: =F21*G21 -> 7965.76 | K21: 0 | L21: =SUM(H21:K21) -> 7965.76 | M21: 878.42 | N21: 211.1 | O21: 5000 | P21: 896.34 | Q21: =SUM(M21:P21) -> 6985.86 | R21: =+L21-Q21 -> 979.9 | T21: 318.6304 | U21: 2244.01 | V21: =+U21+T21 -> 2562.6404 | W21: =+L21 -> 7965.76 | Y21: =+W21+V21 -> 10528.4 | Z21: =+Y21*$Z$12 -> 315.85201 | AA21: =+Y21+Z21 -> 10844.252 | AB21: =+AA21*$AB$14 -> 1735.0804 | AC21: =+AA21+AB21 -> 12579.333
A22: 7 | B22: LOMELI SANAVIA ROSALIA | C22: JURIDICO | D22: DIRECTOR JURIDICO | E22: =+F22*30 -> 37339.5 | F22: 1244.65 | G22: 16 | H22: =F22*G22 -> 19914.4 | K22: 0 | L22: =SUM(H22:K22) -> 19914.4 | M22: 3527.92 | N22: 559.02 | O22: 0 | P22: 0 | Q22: =SUM(M22:P22) -> 4086.94 | R22: =+L22-Q22 -> 15827.46 | T22: 796.576 | U22: 5045 | V22: =+U22+T22 -> 5841.576 | W22: =+L22 -> 19914.4 | Y22: =+W22+V22 -> 25755.976 | Z22: =+Y22*$Z$12 -> 772.67928 | AA22: =+Y22+Z22 -> 26528.655 | AB22: =+AA22*$AB$14 -> 4244.5848 | AC22: =+AA22+AB22 -> 30773.24
A23: 8 | B23: MARTIN DZUL JAVIER ALEJANDRO | C23: JURIDICO | D23: ENCARGADO JURIDICO | E23: =+F23*30 -> 14935.8 | F23: 497.86 | G23: 16 | H23: =F23*G23 -> 7965.76 | K23: 0 | L23: =SUM(H23:K23) -> 7965.76 | M23: 878.42 | N23: 211.1 | O23: 0 | P23: 0 | Q23: =SUM(M23:P23) -> 1089.52 | R23: =+L23-Q23 -> 6876.24 | T23: 318.6304 | U23: 2244.01 | V23: =+U23+T23 -> 2562.6404 | W23: =+L23 -> 7965.76 | Y23: =+W23+V23 -> 10528.4 | Z23: =+Y23*$Z$12 -> 315.85201 | AA23: =+Y23+Z23 -> 10844.252 | AB23: =+AA23*$AB$14 -> 1735.0804 | AC23: =+AA23+AB23 -> 12579.333
A24: 9 | B24: PALMA ANDRADE EDWIN JOSUE | C24: DIRECCION CONSEJO | D24: ASISTENTE DE PROYECTO | E24: =+F24*30 -> 14935.8 | F24: 497.86 | G24: 16 | H24: =F24*G24 -> 7965.76 | K24: 0 | L24: =SUM(H24:K24) -> 7965.76 | M24: 878.42 | N24: 211.1 | O24: 0 | P24: 648.84 | Q24: =SUM(M24:P24) -> 1738.36 | R24: =+L24-Q24 -> 6227.4 | T24: 318.6304 | U24: 2244.01 | V24: =+U24+T24 -> 2562.6404 | W24: =+L24 -> 7965.76 | Y24: =+W24+V24 -> 10528.4 | Z24: =+Y24*$Z$12 -> 315.85201 | AA24: =+Y24+Z24 -> 10844.252 | AB24: =+AA24*$AB$14 -> 1735.0804 | AC24: =+AA24+AB24 -> 12579.333
A25: 10 | B25: QUIÑONES PALMA TOMAS VENTURA | C25: DIRECCION CONSEJO | D25: GERENTE DE MARINA SHARK | E25: =+F25*30 -> 29871.6 | F25: 995.72 | G25: 16 | H25: =F25*G25 -> 15931.52 | K25: 0 | L25: =SUM(H25:K25) -> 15931.52 | M25: 2591.15 | N25: 443.05 | O25: 0 | P25: 0 | Q25: =SUM(M25:P25) -> 3034.2 | R25: =+L25-Q25 -> 12897.32 | T25: 637.2608 | U25: 4111.37 | V25: =+U25+T25 -> 4748.6308 | W25: =+L25 -> 15931.52 | Y25: =+W25+V25 -> 20680.151 | Z25: =+Y25*$Z$12 -> 620.40452 | AA25: =+Y25+Z25 -> 21300.555 | AB25: =+AA25*$AB$14 -> 3408.0889 | AC25: =+AA25+AB25 -> 24708.644
A26: 11 | B26: RAMIREZ AGUILAR ARTURO | C26: DIRECCION CONSEJO | D26: ENCARGADO DE LICITACIONES PUBLICAS | E26: =+F26*30 -> 22403.7 | F26: 746.79 | G26: 16 | H26: =F26*G26 -> 11948.64 | K26: 0 | L26: =SUM(H26:K26) -> 11948.64 | M26: 1729.17 | N26: 327.08 | O26: 0 | P26: 2663.06 | Q26: =SUM(M26:P26) -> 4719.31 | R26: =+L26-Q26 -> 7229.33 | T26: 477.9456 | U26: 3177.71 | V26: =+U26+T26 -> 3655.6556 | W26: =+L26 -> 11948.64 | Y26: =+W26+V26 -> 15604.296 | Z26: =+Y26*$Z$12 -> 468.12887 | AA26: =+Y26+Z26 -> 16072.424 | AB26: =+AA26*$AB$14 -> 2571.5879 | AC26: =+AA26+AB26 -> 18644.012
A27: 14 | B27: RUIZ REYES ITZEL | C27: TESORERIA | D27: ENCARGADA DE TESORERIA | E27: =+F27*30 -> 14935.8 | F27: 497.86 | G27: 16 | H27: =F27*G27 -> 7965.76 | K27: 0 | L27: =SUM(H27:K27) -> 7965.76 | M27: 878.42 | N27: 211.1 | O27: 0 | P27: 1891.16 | Q27: =SUM(M27:P27) -> 2980.68 | R27: =+L27-Q27 -> 4985.08 | T27: 318.6304 | U27: 2244.01 | V27: =+U27+T27 -> 2562.6404 | W27: =+L27 -> 7965.76 | Y27: =+W27+V27 -> 10528.4 | Z27: =+Y27*$Z$12 -> 315.85201 | AA27: =+Y27+Z27 -> 10844.252 | AB27: =+AA27*$AB$14 -> 1735.0804 | AC27: =+AA27+AB27 -> 12579.333
A28: 15 | B28: VELAZQUEZ RODRIGUEZ OMAR | C28: CONTABILIDAD | D28: CONTADOR GENERAL | E28: =+F28*30 -> 22403.7 | F28: 746.79 | G28: 16 | H28: =F28*G28 -> 11948.64 | K28: 0 | L28: =SUM(H28:K28) -> 11948.64 | M28: 1729.17 | N28: 327.08 | O28: 0 | P28: 0 | Q28: =SUM(M28:P28) -> 2056.25 | R28: =+L28-Q28 -> 9892.39 | T28: 477.9456 | U28: 3177.71 | V28: =+U28+T28 -> 3655.6556 | W28: =+L28 -> 11948.64 | Y28: =+W28+V28 -> 15604.296 | Z28: =+Y28*$Z$12 -> 468.12887 | AA28: =+Y28+Z28 -> 16072.424 | AB28: =+AA28*$AB$14 -> 2571.5879 | AC28: =+AA28+AB28 -> 18644.012
... A30: 17 | B30: PUC ZAVALA JOSUE ISRAEL | C30: AUDITORIA | D30: AUDITOR INTERNO | E30: =+F30*30 -> 14935.8 | F30: 497.86 | G30: 16 | H30: =F30*G30 -> 7965.76 | K30: 0 | L30: =SUM(H30:K30) -> 7965.76 | M30: 878.42 | N30: 211.1 | O30: 0 | P30: 0 | Q30: =SUM(M30:P30) -> 1089.52 | R30: =+L30-Q30 -> 6876.24 | T30: 318.6304 | U30: 2244.01 | V30: =+U30+T30 -> 2562.6404 | W30: =+L30 -> 7965.76 | Y30: =+W30+V30 -> 10528.4 | Z30: =+Y30*$Z$12 -> 315.85201 | AA30: =+Y30+Z30 -> 10844.252 | AB30: =+AA30*$AB$14 -> 1735.0804 | AC30: =+AA30+AB30 -> 12579.333
A31: 18 | B31: ALVAREZ VAZQUEZ MONICA | C31: FINANZAS | D31: ASISTENTE DE DIRECCION | E31: =+F31*30 -> 14935.8 | F31: 497.86 | G31: 16 | H31: =F31*G31 -> 7965.76 | L31: =SUM(H31:K31) -> 7965.76 | M31: 878.42 | N31: 211.1 | O31: 900 | P31: 956.06 | Q31: =SUM(M31:P31) -> 2945.58 | R31: =+L31-Q31 -> 5020.18 | T31: 318.6304 | U31: 2244.01 | V31: =+U31+T31 -> 2562.6404 | W31: =+L31 -> 7965.76 | Y31: =+W31+V31 -> 10528.4 | Z31: =+Y31*$Z$12 -> 315.85201 | AA31: =+Y31+Z31 -> 10844.252 | AB31: =+AA31*$AB$14 -> 1735.0804 | AC31: =+AA31+AB31 -> 12579.333
A32: 12 | B32: RAMIREZ MARTINEZ SANDY GRISELL | C32: CONTABILIDAD | D32: AUXILIAR CONTABLE | E32: =+F32*30 -> 14935.8 | F32: 497.86 | G32: 16 | H32: =F32*G32 -> 7965.76 | K32: 0 | L32: =SUM(H32:K32) -> 7965.76 | M32: 878.42 | N32: 211.1 | O32: 0 | P32: 0 | Q32: =SUM(M32:P32) -> 1089.52 | R32: =+L32-Q32 -> 6876.24 | T32: 318.6304 | U32: 2244.01 | V32: =+U32+T32 -> 2562.6404 | W32: =+L32 -> 7965.76 | Y32: =+W32+V32 -> 10528.4 | Z32: =+Y32*$Z$12 -> 315.85201 | AA32: =+Y32+Z32 -> 10844.252 | AB32: =+AA32*$AB$14 -> 1735.0804 | AC32: =+AA32+AB32 -> 12579.333
A33: 19 | B33: HERNANDEZ ALVAREZ EVERARDO DE JESUS | C33: JURIDICO | D33: Control Documental PLD | E33: =+F33*30 -> 14935.8 | F33: 497.86 | G33: 16 | H33: =F33*G33 -> 7965.76 | L33: =SUM(H33:K33) -> 7965.76 | M33: 878.42 | N33: 211.1 | O33: 500 | P33: 2013.94 | Q33: =SUM(M33:P33) -> 3603.46 | R33: =+L33-Q33 -> 4362.3 | T33: 318.6304 | U33: 2244.01 | V33: =+U33+T33 -> 2562.6404 | W33: =+L33 -> 7965.76 | Y33: =+W33+V33 -> 10528.4 | Z33: =+Y33*$Z$12 -> 315.85201 | AA33: =+Y33+Z33 -> 10844.252 | AB33: =+AA33*$AB$14 -> 1735.0804 | AC33: =+AA33+AB33 -> 12579.333
A34: 20 | B34: DIAZ BERMUDEZ ADRIANA DEL PILAR | C34: TESORERIA | D34: AUXILIAR DE TESORERIA | E34: =+F34*30 -> 14935.8 | F34: 497.86 | G34: 16 | H34: =F34*G34 -> 7965.76 | L34: =SUM(H34:K34) -> 7965.76 | M34: 878.42 | N34: 211.1 | O34: 0 | P34: 0 | Q34: =SUM(M34:P34) -> 1089.52 | R34: =+L34-Q34 -> 6876.24 | T34: 318.6304 | U34: 2244.01 | V34: =+U34+T34 -> 2562.6404 | W34: =+L34 -> 7965.76 | Y34: =+W34+V34 -> 10528.4 | Z34: =+Y34*$Z$12 -> 315.85201 | AA34: =+Y34+Z34 -> 10844.252 | AB34: =+AA34*$AB$14 -> 1735.0804 | AC34: =+AA34+AB34 -> 12579.333
A35: 22 | B35: PONCE MELENDEZ FLAVIO MAURICIO | C35: FINANZAS | D35: DIRECTOR DE ADMINISTRACION Y FINANZAS | E35: =+F35*30 -> 37339.5 | F35: 1244.65 | G35: 16 | H35: =F35*G35 -> 19914.4 | L35: =SUM(H35:K35) -> 19914.4 | M35: 3527.92 | N35: 559.02 | O35: 0 | P35: 0 | Q35: =SUM(M35:P35) -> 4086.94 | R35: =+L35-Q35 -> 15827.46 | T35: 796.576 | U35: 5045 | V35: =+U35+T35 -> 5841.576 | W35: =+L35 -> 19914.4 | Y35: =+W35+V35 -> 25755.976 | Z35: =+Y35*$Z$12 -> 772.67928 | AA35: =+Y35+Z35 -> 26528.655 | AB35: =+AA35*$AB$14 -> 4244.5848 | AC35: =+AA35+AB35 -> 30773.24
A36: 21 | B36: ANAYA NOLASCO ALBERTO | C36: CONSTRUCCION | D36: DIRECTOR DE CONSTRUCCION | E36: =+F36*30 -> 37339.5 | F36: 1244.65 | G36: 16 | H36: =F36*G36 -> 19914.4 | L36: =SUM(H36:K36) -> 19914.4 | M36: 3527.92 | N36: 559.02 | O36: 0 | P36: 0 | Q36: =SUM(M36:P36) -> 4086.94 | R36: =+L36-Q36 -> 15827.46 | T36: 796.576 | U36: 5045 | V36: =+U36+T36 -> 5841.576 | W36: =+L36 -> 19914.4 | Y36: =+W36+V36 -> 25755.976 | Z36: =+Y36*$Z$12 -> 772.67928 | AA36: =+Y36+Z36 -> 26528.655 | AB36: =+AA36*$AB$14 -> 4244.5848 | AC36: =+AA36+AB36 -> 30773.24
A37: 22 | B37: PABLO HERNANDEZ CECILIA | C37: ZEN GARDEN | D37: PROJECT MANAGER JR | E37: 35000 | F37: 497.86 | G37: 16 | H37: =F37*G37 -> 7965.76 | L37: =SUM(H37:K37) -> 7965.76 | M37: 878.42 | N37: 211.1 | O37: 0 | P37: 717.52 | Q37: =SUM(M37:P37) -> 1807.04 | R37: =+L37-Q37 -> 6158.72 | T37: 318.6304 | U37: 2244.01 | V37: =+U37+T37 -> 2562.6404 | W37: =+L37 -> 7965.76 | Y37: =+W37+V37 -> 10528.4 | Z37: =+Y37*$Z$12 -> 315.85201 | AA37: =+Y37+Z37 -> 10844.252 | AB37: =+AA37*$AB$14 -> 1735.0804 | AC37: =+AA37+AB37 -> 12579.333
A38: 1 | B38: MORENO FERNANDEZ ANA PAULINA | C38: RHE WAVE Y TORRE SHARK | D38: PROJECT MANAGER JR | E38: 35000 | F38: 497.86 | G38: 16 | H38: =F38*G38 -> 7965.76 | L38: =SUM(H38:K38) -> 7965.76 | M38: 878.42 | N38: 211.1 | O38: 0 | P38: 0 | Q38: =SUM(M38:P38) -> 1089.52 | R38: =+L38-Q38 -> 6876.24 | T38: 318.6304 | U38: 2244.01 | V38: =+U38+T38 -> 2562.6404 | W38: =+L38 -> 7965.76 | Y38: =+W38+V38 -> 10528.4 | Z38: =+Y38*$Z$12 -> 315.85201 | AA38: =+Y38+Z38 -> 10844.252 | AB38: =+AA38*$AB$14 -> 1735.0804 | AC38: =+AA38+AB38 -> 12579.333 | AD38: PCE LOGISTICA
A39: 2 | B39: BURGOS CANTE ALEXIS ANTONIO | C39: SISTEMAS | D39: AUXILIAR DE SISTEMAS TI | E39: =F39*30 -> 11202 | F39: 373.4 | G39: 16 | H39: =F39*G39 -> 5974.4 | L39: =SUM(H39:K39) -> 5974.4 | M39: 518.38 | N39: 153.12 | O39: 0 | P39: 0 | Q39: =SUM(M39:P39) -> 671.5 | R39: =+L39-Q39 -> 5302.9 | S39: =+M39-R39 -> -4784.52 | T39: 238.976 | U39: 1734.9 | V39: =+U39+T39 -> 1973.876 | W39: =+L39 -> 5974.4 | Y39: =+W39+V39 -> 7948.276 | Z39: =+Y39*$Z$12 -> 238.44828 | AA39: =+Y39+Z39 -> 8186.7243 | AB39: =+AA39*$AB$14 -> 1309.8759 | AC39: =+AA39+AB39 -> 9496.6002 | AD39: PCE LOGISTICA
A40: 3 | B40: CAMARA COBOJ CELESTE ESMERALDA | C40: CAPITAL HUMANO | D40: NOMINISTA | E40: 16000 | F40: 497.86 | G40: 16 | H40: =F40*G40 -> 7965.76 | L40: =SUM(H40:K40) -> 7965.76 | M40: 878.42 | N40: 211.1 | O40: 0 | P40: 2386.4 | Q40: =SUM(M40:P40) -> 3475.92 | R40: =+L40-Q40 -> 4489.84 | T40: 318.6304 | U40: 2244.01 | V40: =+U40+T40 -> 2562.6404 | W40: =+L40 -> 7965.76 | Y40: =+W40+V40 -> 10528.4 | Z40: =+Y40*$Z$12 -> 315.85201 | AA40: =+Y40+Z40 -> 10844.252 | AB40: =+AA40*$AB$14 -> 1735.0804 | AC40: =+AA40+AB40 -> 12579.333 | AD40: PCE LOGISTICA
B41: MURGA CHAVEZ FATIMA DE JESUS | C41: ADMINISTRACION | D41: DIRECTOR DE ADMINISTRACION Y FINANZAS | F41: 278.8 | G41: 15 | H41: =F41*G41 -> 4182 | L41: =SUM(H41:K41) -> 4182 | M41: 0 | N41: 0 | O41: 0 | P41: 0 | Q41: =SUM(M41:P41) -> 0 | R41: =+L41-Q41 -> 4182 | T41: 167.28 | U41: 1298.32 | V41: =+U41+T41 -> 1465.6 | W41: =+L41 -> 4182 | Y41: =+W41+V41 -> 5647.6 | Z41: =+Y41*$Z$12 -> 169.428 | AA41: =+Y41+Z41 -> 5817.028 | AB41: =+AA41*$AB$14 -> 930.72448 | AC41: =+AA41+AB41 -> 6747.7525 | AD41: PCE LOGISTICA
B42: FONSECA ZACARIAS SARA AMAYRANI | C42: CAPITAL HUMANO | D42: RECEPCIONISTA | E42: =F42*30 -> 8460 | F42: 282 | G42: 5 | H42: =F42*G42 -> 1410 | L42: =SUM(H42:K42) -> 1410 | M42: 0 | N42: 35.14 | O42: 0 | P42: 0 | Q42: 0 | R42: =+L42-Q42 -> 1410 | T42: 56.4 | U42: 403.09 | V42: =+U42+T42 -> 459.49 | W42: =+L42 -> 1410 | Y42: =+W42+V42 -> 1869.49 | Z42: =+Y42*$Z$12 -> 56.0847 | AA42: =+Y42+Z42 -> 1925.5747 | AB42: =+AA42*$AB$14 -> 308.09195 | AC42: =+AA42+AB42 -> 2233.6667 | AD42: PCE LOGISTICA
E43: =SUM(E16:E42) -> 523864.4 | F43: =SUM(F16:F42) -> 16367.86 | G43: =SUM(G16:G42) -> 420 | H43: =SUM(H16:H42) -> 258504.96 | I43: =SUM(I16:I42) -> 0 | J43: =SUM(J16:J42) -> 0 | K43: =SUM(K16:K42) -> 0 | L43: =SUM(L16:L42) -> 258504.96 | ... AC43: =SUM(AC16:AC42) -> 405287.08 | AD43: =SUM(AD16:AD41) -> 0
S45: =+S43-#REF! -> #REF!
B46: NUEVOS
B47: BAJAS/FINIQUITO | AB47: FINIQUITO
AB48: GRAN TOTAL | AC48: =+AC43+AC47 -> 405287.08
AB50: YUKAWA | AC50: =SUM(AC16:AC37) -> 361650.39
AB51: PCE | AC51: =AC42+AC41+AC40+AC39+AC38 -> 43636.685

Sheet SHARK
A9: CONSTRUCTORA L. SHARK
A10: =+'LUXIMIA '!A11 -> 02. DEL 16-31 ENERO 2025 | E10: SUELDO BRUTO | AA10: FACTURACION
N11: TOTAL PERCEPCIONES | U11: NETO | AB11: 0.03
A12: CÓDIGO | B12: NOMBRE | C12: DEPTO | D12: PUESTO | E12: NETO MENSUAL | F12: SDO | G12: DIAS | H12: SUELDO | I12: VACACIONES | J12: PRIMA VACACIONAL | K12: AGUINALDO | L12: DIA TRABAJADO PEND | M12: SUBSIDIO | O12: SUBSIDIO | P12: ISR | Q12: IMSS | R12: PRESTAMO | S12: INFONAVIT | T12: TOTAL DEDUCCIONES | V12: ISN | W12: PREVIO COSTO SOCIAL | X12: TOTAL CARGA SOCIAL | Y12: TOTAL NOMINA | AA12: NOMINAS Y COSTOS TRIBUTARIO | AB12: COMISION | AC12: SUB-TOTAL | AD12: IVA | AE12: TOTAL FACTURACION
AD13: 0.16
A15: 1 | B15: CANO SANCHEZ VIVIANA BERENICE | C15: ADMINISTRACION DE OBRA | D15: ANALISTA DE INFORMACION ENKONTROL | E15: =+F15*30 -> 14935.8 | F15: 497.86 | G15: 16 | H15: =F15*G15 -> 7965.76 | I15: 0 | J15: 0 | K15: 0 | L15: 0 | M15: 0 | N15: =SUM(H15:M15) -> 7965.76 | O15: 0 | P15: 878.42 | Q15: 211.1 | S15: 1888.37 | T15: =SUM(O15:S15) -> 2977.89 | U15: =+N15-T15 -> 4987.87 | V15: 318.6304 | W15: 2244.01 | X15: =+W15+V15 -> 2562.6404 | Y15: =+N15 -> 7965.76 | AA15: =+Y15+X15 -> 10528.4 | AB15: =+AA15*$AB$11 -> 315.85201 | AC15: =+AA15+AB15 -> 10844.252 | AD15: =+AC15*$AD$13 -> 1735.0804 | AE15: =+AC15+AD15 -> 12579.333
A16: 2 | B16: MENEZ MARRUFO DANIEL ABEL | C16: COSTOS | D16: GERENTE DE COSTOS | E16: =+F16*30 -> 29871.6 | F16: 995.72 | G16: 16 | H16: =F16*G16 -> 15931.52 | I16: 0 | J16: 0 | K16: 0 | L16: 0 | M16: 0 | N16: =SUM(H16:M16) -> 15931.52 | O16: 0 | P16: 2591.15 | Q16: 443.05 | S16: 0 | T16: =SUM(O16:S16) -> 3034.2 | U16: =+N16-T16 -> 12897.32 | V16: 637.2608 | W16: 4111.37 | X16: =+W16+V16 -> 4748.6308 | Y16: =+N16 -> 15931.52 | AA16: =+Y16+X16 -> 20680.151 | AB16: =+AA16*$AB$11 -> 620.40452 | AC16: =+AA16+AB16 -> 21300.555 | AD16: =+AC16*$AD$13 -> 3408.0889 | AE16: =+AC16+AD16 -> 24708.644
A17: 3 | B17: SORIANO DIAZ CUAUHTEMOC | C17: CONSTRUCCION | D17: SUPERINTENDENTE GRAL DE OBRA | E17: =+F17*30 -> 22403.7 | F17: 746.79 | G17: 16 | H17: =F17*G17 -> 11948.64 | I17: 0 | J17: 0 | K17: 0 | L17: 0 | M17: 0 | N17: =SUM(H17:M17) -> 11948.64 | O17: 0 | P17: 1729.17 | Q17: 327.08 | S17: 0 | T17: =SUM(O17:S17) -> 2056.25 | U17: =+N17-T17 -> 9892.39 | V17: 477.9456 | W17: 3177.71 | X17: =+W17+V17 -> 3655.6556 | Y17: =+N17 -> 11948.64 | AA17: =+Y17+X17 -> 15604.296 | AB17: =+AA17*$AB$11 -> 468.12887 | AC17: =+AA17+AB17 -> 16072.424 | AD17: =+AC17*$AD$13 -> 2571.5879 | AE17: =+AC17+AD17 -> 18644.012
A18: 4 | B18: ESCAMILLA PERERA DULCE MARICRUZ | C18: POSTVENTA | D18: ENCARGADA CONTROL DE CALIDAD | E18: =+F18*30 -> 14935.8 | F18: 497.86 | G18: 16 | H18: =F18*G18 -> 7965.76 | I18: 0 | J18: 0 | K18: 0 | L18: 0 | M18: 0 | N18: =SUM(H18:M18) -> 7965.76 | O18: 0 | P18: 878.42 | Q18: 211.1 | S18: 0 | T18: =SUM(O18:S18) -> 1089.52 | U18: =+N18-T18 -> 6876.24 | V18: 318.6304 | W18: 2244.01 | X18: =+W18+V18 -> 2562.6404 | Y18: =+N18 -> 7965.76 | AA18: =+Y18+X18 -> 10528.4 | AB18: =+AA18*$AB$11 -> 315.85201 | AC18: =+AA18+AB18 -> 10844.252 | AD18: =+AC18*$AD$13 -> 1735.0804 | AE18: =+AC18+AD18 -> 12579.333
A19: 5 | B19: MAGAA GONZALEZ CORINA SOFIA | C19: VENTAS | D19: ASISTENTE DE DIRECCION | E19: =+F19*30 -> 14935.8 | F19: 497.86 | G19: 16 | H19: =F19*G19 -> 7965.76 | I19: 0 | J19: 0 | K19: 0 | L19: 0 | M19: 0 | N19: =SUM(H19:M19) -> 7965.76 | O19: 0 | P19: 878.42 | Q19: 211.1 | S19: 1372.57 | T19: =SUM(O19:S19) -> 2462.09 | U19: =+N19-T19 -> 5503.67 | V19: 318.6304 | W19: 2244.01 | X19: =+W19+V19 -> 2562.6404 | Y19: =+N19 -> 7965.76 | Z19: =+O19 -> 0 | AA19: =+Y19+X19 -> 10528.4 | AB19: =+AA19*$AB$11 -> 315.85201 | AC19: =+AA19+AB19 -> 10844.252 | AD19: =+AC19*$AD$13 -> 1735.0804 | AE19: =+AC19+AD19 -> 12579.333
A20: 6 | B20: CRUZ IZQUIERDO SAMUEL ERASMO | C20: POSTVENTA | D20: Auxiliar de Calidad y Postventa | E20: =+F20*30 -> 14935.8 | F20: 497.86 | G20: 16 | H20: =F20*G20 -> 7965.76 | I20: 0 | J20: 0 | K20: 0 | L20: 0 | M20: 0 | N20: =SUM(H20:M20) -> 7965.76 | O20: 0 | P20: 878.42 | Q20: 211.1 | S20: 0 | T20: =SUM(O20:S20) -> 1089.52 | U20: =+N20-T20 -> 6876.24 | V20: 318.6304 | W20: 2244.01 | X20: =+W20+V20 -> 2562.6404 | Y20: =+N20 -> 7965.76 | Z20: =+O20 -> 0 | AA20: =+Y20+X20 -> 10528.4 | AB20: =+AA20*$AB$11 -> 315.85201 | AC20: =+AA20+AB20 -> 10844.252 | AD20: =+AC20*$AD$13 -> 1735.0804 | AE20: =+AC20+AD20 -> 12579.333
A21: 7 | B21: PIÑA GARCIA RICARDO | C21: MERCADOTECNIA | D21: DISEÑADOR GRAFICO | E21: 20000 | F21: 497.86 | G21: 16 | H21: =F21*G21 -> 7965.76 | N21: =SUM(H21:M21) -> 7965.76 | P21: 878.42 | Q21: 211.1 | S21: 0 | T21: =SUM(O21:S21) -> 1089.52 | U21: =+N21-T21 -> 6876.24 | V21: 318.6304 | W21: 2244.01 | X21: =+W21+V21 -> 2562.6404 | Y21: =+N21 -> 7965.76 | AA21: =+Y21+X21 -> 10528.4 | AB21: =+AA21*$AB$11 -> 315.85201 | AC21: =+AA21+AB21 -> 10844.252 | AD21: =+AC21*$AD$13 -> 1735.0804 | AE21: =+AC21+AD21 -> 12579.333 | AF21: PCE LOGISTICA
E22: =SUM(E15:E21) -> 132018.5 | F22: =SUM(F15:F21) -> 4231.81 | G22: =SUM(G15:G21) -> 112 | H22: =SUM(H15:H21) -> 67708.96 | I22: =SUM(I15:I21) -> 0 | J22: =SUM(J15:J21) -> 0 | K22: =SUM(K15:K21) -> 0 | L22: =SUM(L15:L21) -> 0 | ... AE22: =SUM(AE15:AE21) -> 106249.32
B24: NUEVOS | Z24: =Z22-Z23 -> 0
B25: BAJAS/FINIQUITO | AD25: FINQUITO | AE25: 0
AD26: GRAN TOTAL | AE26: =+AE22+AE25+AE24 -> 106249.32

Sheet PETREOS
A9: PROCESADOS PETREOS LUXIMIA
A10: =+'LUXIMIA '!A11 -> 02. DEL 16-31 ENERO 2025 | E10: SUELDO BRUTO | X10: FACTURACION
L11: TOTAL PERCEPCIONES | R11: NETO | Y11: 0.03
A12: CÓDIGO | B12: NOMBRE | C12: DEPTO | D12: PUESTO | E12: NETO MENSUAL | F12: SDO | G12: DIAS | H12: SUELDO | I12: PRIMA VACACIONAL | J12: DIA TRABAJADO PEND | K12: SUBSIDIO | M12: ISR | N12: IMSS | O12: PRESTAMO | P12: INFONAVIT | Q12: TOTAL DEDUCCIONES | S12: 0.04 | T12: PREVIO COSTO SOCIAL | U12: TOTAL CARGA SOCIAL | V12: TOTAL NOMINA | X12: NOMINAS Y COSTOS TRIBUTARIO | Y12: COMISION | Z12: SUB-TOTAL | AA12: IVA | AB12: TOTAL FACTURACION
AA13: 0.16
A14: 1 | B14: DANIEL MARTIN GONZALEZ AGUILAR | C14: BANCO DE MATERIAL | D14: GERENTE BANCO DE MATERIALES Y MAQUINARIA | E14: =+F14*30 -> 29871.6 | F14: 995.72 | G14: 16 | H14: =+F14*G14 -> 15931.52 | L14: =SUM(H14:K14) -> 15931.52 | M14: 2591.15 | N14: 443.05 | P14: 2103.92 | Q14: =SUM(M14:P14) -> 5138.12 | R14: =+L14-Q14 -> 10793.4 | S14: 637.2608 | T14: 4011.37 | U14: =S14+T14 -> 4648.6308 | V14: =+L14 -> 15931.52 | X14: =+V14+U14 -> 20580.151 | Y14: =+X14*$Y$11 -> 617.40452 | Z14: =+X14+Y14 -> 21197.555 | AA14: =+Z14*$AA$13 -> 3391.6089 | AB14: =+Z14+AA14 -> 24589.164
B15: RAYO REYES FERNANDO | C15: BANCO DE MATERIAL | E15: =F15*30 -> 14935.8 | F15: 497.86 | G15: 5 | H15: =+F15*G15 -> 2489.3 | L15: =SUM(H15:K15) -> 2489.3 | M15: 259.36 | N15: 65.98 | Q15: =SUM(M15:P15) -> 325.34 | R15: =+L15-Q15 -> 2163.96 | S15: 99.572 | T15: 670.36 | U15: =S15+T15 -> 769.932 | V15: =+L15 -> 2489.3 | X15: =+V15+U15 -> 3259.232 | Y15: =+X15*$Y$11 -> 97.77696 | Z15: =+X15+Y15 -> 3357.009 | AA15: =+Z15*$AA$13 -> 537.12143 | AB15: =+Z15+AA15 -> 3894.1304
E16: =SUM(E14:E15) -> 44807.4 | F16: =SUM(F14:F15) -> 1493.58 | G16: =SUM(G14:G15) -> 21 | H16: =SUM(H14:H15) -> 18420.82 | I16: =SUM(I14:I15) -> 0 | J16: =SUM(J14:J15) -> 0 | K16: =SUM(K14:K15) -> 0 | L16: =SUM(L14:L15) -> 18420.82 | ... AB16: =SUM(AB14:AB15) -> 28483.295
B18: NUEVOS
B19: BAJAS/FINIQUITO | AA19: FINQUITO | AB19: =+'[9]RESUMEN LUXIMIA,SHARK1'!AB38 -> 0
AA20: GRAN TOTAL | AB20: =+AB16+AB19+AB18 -> 28483.295

Sheet RESUMEN PCE
A9: NOMINA QUINCENAL | I9: NOMINA QUINCENAL | Q9: NOMINA QUINCENAL
A10: =+'LUXIMIA '!A11 -> 02. DEL 16-31 ENERO 2025 | I10: =+'LUXIMIA '!I11 -> 0 | Q10: =+'LUXIMIA '!Q11 -> 0
A12: FISCAL | I12: FISCAL | Q12: FISCAL
A13: LUXIMIA | I13: SHARK | Q13: PETREOS
B16: NOMINA FISCAL | C16: COSTO SOCIAL | D16: 0.03 | E16: SUBTOTAL | F16: IVA | G16: TOTAL | J16: NOMINA FISCAL | K16: COSTO SOCIAL | L16: 0.03 | M16: SUBTOTAL | N16: IVA | O16: TOTAL | R16: NOMINA FISCAL | S16: COSTO SOCIAL | T16: 0.03 | U16: SUBTOTAL | V16: IVA | W16: TOTAL
A17: ADMINISTRACIÓN | B17: =+'LUXIMIA '!W41 -> 4182 | C17: =+'LUXIMIA '!V41 -> 1465.6 | D17: =+(B17+C17)*$D$16 -> 169.428 | E17: =+B17+D17+C17 -> 5817.028 | F17: =+E17*16% -> 930.72448 | G17: =+E17+F17 -> 6747.7525 | I17: ADMINISTRACIÓN | J17: 0 | K17: 0 | L17: =+(J17+K17)*$D$16 -> 0 | M17: =+J17+L17+K17 -> 0 | N17: =+M17*16% -> 0 | O17: =+M17+N17 -> 0 | Q17: ADMINISTRACIÓN | R17: 0 | S17: 0 | T17: =+(R17+S17)*$D$16 -> 0 | U17: =+R17+T17+S17 -> 0 | V17: =+U17*16% -> 0 | W17: =+U17+V17 -> 0
A18: CAPITAL HUMANO | B18: =+'LUXIMIA '!W42+'LUXIMIA '!W40 -> 9375.76 | C18: =+'LUXIMIA '!V42+'LUXIMIA '!V40 -> 3022.1304 | D18: =+(B18+C18)*$D$16 -> 371.93671 | E18: =+B18+D18+C18 -> 12769.827 | F18: =+E18*16% -> 2043.1723 | G18: =+E18+F18 -> 14812.999 | I18: CAPITAL HUMANO | J18: =+'LUXIMIA '!AE40 -> 0 | L18: =+(J18+K18)*$D$16 -> 0 | M18: =+J18+L18+K18 -> 0 | N18: =+M18*16% -> 0 | O18: =+M18+N18 -> 0 | Q18: CAPITAL HUMANO | R18: =+'LUXIMIA '!AM40 -> 0 | T18: =+(R18+S18)*$D$16 -> 0 | U18: =+R18+T18+S18 -> 0 | V18: =+U18*16% -> 0 | W18: =+U18+V18 -> 0
A19: CONTABILIDAD | B19: 0 | C19: 0 | D19: =+(B19+C19)*$D$16 -> 0 | E19: =+B19+D19+C19 -> 0 | F19: =+E19*16% -> 0 | G19: =+E19+F19 -> 0 | I19: CONTABILIDAD | J19: 0 | K19: 0 | L19: =+(J19+K19)*$D$16 -> 0 | M19: =+J19+L19+K19 -> 0 | N19: =+M19*16% -> 0 | O19: =+M19+N19 -> 0 | Q19: CONTABILIDAD | R19: 0 | S19: 0 | T19: =+(R19+S19)*$D$16 -> 0 | U19: =+R19+T19+S19 -> 0 | V19: =+U19*16% -> 0 | W19: =+U19+V19 -> 0
A20: DIRECCIÓN CONSEJO | B20: 0 | C20: 0 | D20: =+(B20+C20)*$D$16 -> 0 | E20: =+B20+D20+C20 -> 0 | F20: =+E20*16% -> 0 | G20: =+E20+F20 -> 0 | I20: DIRECCIÓN CONSEJO | J20: 0 | K20: 0 | L20: =+(J20+K20)*$D$16 -> 0 | M20: =+J20+L20+K20 -> 0 | N20: =+M20*16% -> 0 | O20: =+M20+N20 -> 0 | Q20: DIRECCIÓN CONSEJO | R20: 0 | S20: 0 | T20: =+(R20+S20)*$D$16 -> 0 | U20: =+R20+T20+S20 -> 0 | V20: =+U20*16% -> 0 | W20: =+U20+V20 -> 0
A21: JURIDICO | B21: 0 | C21: 0 | D21: =+(B21+C21)*$D$16 -> 0 | E21: =+B21+D21+C21 -> 0 | F21: =+E21*16% -> 0 | G21: =+E21+F21 -> 0 | I21: JURIDICO | J21: 0 | K21: 0 | L21: =+(J21+K21)*$D$16 -> 0 | M21: =+J21+L21+K21 -> 0 | N21: =+M21*16% -> 0 | O21: =+M21+N21 -> 0 | Q21: JURIDICO | R21: 0 | S21: 0 | T21: =+(R21+S21)*$D$16 -> 0 | U21: =+R21+T21+S21 -> 0 | V21: =+U21*16% -> 0 | W21: =+U21+V21 -> 0
A22: FINANZAS | B22: 0 | C22: 0 | D22: =+(B22+C22)*$D$16 -> 0 | E22: =+B22+D22+C22 -> 0 | F22: =+E22*16% -> 0 | G22: =+E22+F22 -> 0 | I22: FINANZAS | J22: 0 | K22: 0 | L22: =+(J22+K22)*$D$16 -> 0 | M22: =+J22+L22+K22 -> 0 | N22: =+M22*16% -> 0 | O22: =+M22+N22 -> 0 | Q22: FINANZAS | R22: 0 | S22: 0 | T22: =+(R22+S22)*$D$16 -> 0 | U22: =+R22+T22+S22 -> 0 | V22: =+U22*16% -> 0 | W22: =+U22+V22 -> 0
A23: SEGURIDAD | B23: 0 | C23: 0 | D23: =+(B23+C23)*$D$16 -> 0 | E23: =+B23+D23+C23 -> 0 | F23: =+E23*16% -> 0 | G23: =+E23+F23 -> 0 | I23: SEGURIDAD | J23: 0 | K23: 0 | L23: =+(J23+K23)*$D$16 -> 0 | M23: =+J23+L23+K23 -> 0 | N23: =+M23*16% -> 0 | O23: =+M23+N23 -> 0 | Q23: SEGURIDAD | R23: 0 | S23: 0 | T23: =+(R23+S23)*$D$16 -> 0 | U23: =+R23+T23+S23 -> 0 | V23: =+U23*16% -> 0 | W23: =+U23+V23 -> 0
A24: SISTEMAS | B24: =+'LUXIMIA '!W39 -> 5974.4 | C24: =+'LUXIMIA '!V39 -> 1973.876 | D24: =+(B24+C24)*$D$16 -> 238.44828 | E24: =+B24+D24+C24 -> 8186.7243 | F24: =+E24*16% -> 1309.8759 | G24: =+E24+F24 -> 9496.6002 | I24: SISTEMAS | J24: =+'LUXIMIA '!AG39 -> 0 | K24: 0 | L24: =+(J24+K24)*$D$16 -> 0 | M24: =+J24+L24+K24 -> 0 | N24: =+M24*16% -> 0 | O24: =+M24+N24 -> 0 | Q24: SISTEMAS | R24: =+'LUXIMIA '!AO39 -> 0 | S24: 0 | T24: =+(R24+S24)*$D$16 -> 0 | U24: =+R24+T24+S24 -> 0 | V24: =+U24*16% -> 0 | W24: =+U24+V24 -> 0
A25: ZEN GARDENS | B25: =+'LUXIMIA '!W38 -> 7965.76 | C25: =+'LUXIMIA '!V38 -> 2562.6404 | D25: =+(B25+C25)*$D$16 -> 315.85201 | E25: =+B25+D25+C25 -> 10844.252 | F25: =+E25*16% -> 1735.0804 | G25: =+E25+F25 -> 12579.333 | I25: ZEN GARDENS | J25: =+'LUXIMIA '!AG38 -> 0 | K25: 0 | L25: =+(J25+K25)*$D$16 -> 0 | M25: =+J25+L25+K25 -> 0 | N25: =+M25*16% -> 0 | O25: =+M25+N25 -> 0 | Q25: ZEN GARDENS | R25: =+'LUXIMIA '!AO38 -> 0 | S25: 0 | T25: =+(R25+S25)*$D$16 -> 0 | U25: =+R25+T25+S25 -> 0 | V25: =+U25*16% -> 0 | W25: =+U25+V25 -> 0
A26: CONTROL DE ACCESO | B26: 0 | C26: 0 | D26: =+(B26+C26)*$D$16 -> 0 | E26: =+B26+D26+C26 -> 0 | F26: =+E26*16% -> 0 | G26: =+E26+F26 -> 0 | I26: AUDITORIA | J26: 0 | K26: 0 | L26: =+(J26+K26)*$D$16 -> 0 | M26: =+J26+L26+K26 -> 0 | N26: =+M26*16% -> 0 | O26: =+M26+N26 -> 0 | Q26: AUDITORIA | R26: 0 | S26: 0 | T26: =+(R26+S26)*$D$16 -> 0 | U26: =+R26+T26+S26 -> 0 | V26: =+U26*16% -> 0 | W26: =+U26+V26 -> 0
A27: TESORERIA | B27: 0 | C27: 0 | D27: =+(B27+C27)*$D$16 -> 0 | E27: =+B27+D27+C27 -> 0 | F27: =+E27*16% -> 0 | G27: =+E27+F27 -> 0 | I27: TESORERIA | J27: 0 | K27: 0 | L27: =+(J27+K27)*$D$16 -> 0 | M27: =+J27+L27+K27 -> 0 | N27: =+M27*16% -> 0 | O27: =+M27+N27 -> 0 | Q27: TESORERIA | R27: 0 | S27: 0 | T27: =+(R27+S27)*$D$16 -> 0 | U27: =+R27+T27+S27 -> 0 | V27: =+U27*16% -> 0 | W27: =+U27+V27 -> 0
A28: MERCADOTENEA | C28: 0 | D28: =+(B28+C28)*$D$16 -> 0 | E28: =+B28+D28+C28 -> 0 | F28: =+E28*16% -> 0 | G28: =+E28+F28 -> 0 | I28: MERCADOTENEA | J28: =+SHARK!H21 -> 7965.76 | K28: =+SHARK!X21 -> 2562.6404 | L28: =+(J28+K28)*$D$16 -> 315.85201 | M28: =+J28+L28+K28 -> 10844.252 | N28: =+M28*16% -> 1735.0804 | O28: =+M28+N28 -> 12579.333 | Q28: BANCO DE MATERIAL | R28: =+PETREOS!V15 -> 2489.3 | S28: =+PETREOS!U15 -> 769.932 | T28: =+(R28+S28)*$D$16 -> 97.77696 | U28: =+R28+T28+S28 -> 3357.009 | V28: =+U28*16% -> 537.12143 | W28: =+U28+V28 -> 3894.1304
C29: 0 | D29: =+(B29+C29)*$D$16 -> 0 | E29: =+B29+D29+C29 -> 0 | F29: =+E29*16% -> 0 | G29: =+E29+F29 -> 0 | K29: 0 | L29: =+(J29+K29)*$D$16 -> 0 | M29: =+J29+L29+K29 -> 0 | N29: =+M29*16% -> 0 | O29: =+M29+N29 -> 0 | S29: 0 | T29: =+(R29+S29)*$D$16 -> 0 | U29: =+R29+T29+S29 -> 0 | V29: =+U29*16% -> 0 | W29: =+U29+V29 -> 0
B30: =SUM(B17:B29) -> 27497.92 | C30: =SUM(C17:C29) -> 9024.2468 | D30: =SUM(D17:D29) -> 1095.665 | E30: =SUM(E17:E29) -> 37617.832 | F30: =SUM(F17:F29) -> 6018.8531 | G30: =SUM(G17:G29)+G34 -> 43636.685 | J30: =SUM(J17:J29) -> 7965.76 | K30: =SUM(K17:K29) -> 2562.6404 | L30: =SUM(L17:L29) -> 315.85201 | M30: =SUM(M17:M29) -> 10844.252 | N30: =SUM(N17:N29) -> 1735.0804 | O30: =SUM(O17:O29)+O34 -> 12579.333 | R30: =SUM(R17:R29) -> 2489.3 | S30: =SUM(S17:S29) -> 769.932 | T30: =SUM(T17:T29) -> 97.77696 | U30: =SUM(U17:U29) -> 3357.009 | V30: =SUM(V17:V29) -> 537.12143 | W30: =SUM(W17:W29)+W34 -> 3894.1304
F35: GRAN TOTAL | G35: =G30+G43 -> 43636.685 | N35: GRAN TOTAL | O35: =O30+O43 -> 12579.333 | V35: GRAN TOTAL | W35: =W30+W43 -> 3894.1304
N39: 10647.327 | O39: =O35/1.16 -> 10844.252

Sheet RESUMEN LUXIMIA,SHARK1
A9: NOMINA QUINCENAL | N9: NOMINA QUINCENAL | AA9: NOMINA QUINCENAL
A10: =+'LUXIMIA '!A11 -> 02. DEL 16-31 ENERO 2025 | N10: =+SHARK!A10 -> 02. DEL 16-31 ENERO 2025 | AA10: =+[9]SHARK!P10 -> 0
A12: FISCAL | N12: FISCAL | AA12: FISCAL
A13: LUXIMIA | N13: SHARK | AA13: PETREO
B16: NOMINA FISCAL | C16: COSTO SOCIAL | D16: 0.03 | E16: SUBTOTAL | F16: IVA | G16: TOTAL | O16: NOMINA FISCAL | P16: COSTO SOCIAL | Q16: 0.03 | R16: SUBTOTAL | S16: IVA | T16: TOTAL | AB16: NOMINA FISCAL | AC16: COSTO SOCIAL | AD16: 0.03 | AE16: SUBTOTAL | AF16: IVA | AG16: TOTAL
A17: ADMINISTRACIÓN | B17: =+'LUXIMIA '!H36 -> 19914.4 | C17: =+'LUXIMIA '!V36 -> 5841.576 | D17: =+(B17+C17)*$D$16 -> 772.67928 | E17: =+B17+D17+C17 -> 26528.655 | F17: =+E17*16% -> 4244.5848 | G17: =+E17+F17 -> 30773.24 | N17: ADMINISTRACIÓN | O17: =+SHARK!H15 -> 7965.76 | P17: =+SHARK!X15 -> 2562.6404 | Q17: =+(O17+P17)*$D$16 -> 315.85201 | R17: =+O17+Q17+P17 -> 10844.252 | S17: =+R17*16% -> 1735.0804 | T17: =+R17+S17 -> 12579.333 | AA17: BANCO DE MATERIAL | AB17: =+PETREOS!V14 -> 15931.52 | AC17: =+PETREOS!U14 -> 4648.6308 | AD17: =+(AB17+AC17)*$D$16 -> 617.40452 | AE17: =+AB17+AD17+AC17 -> 21197.555 | AF17: =+AE17*16% -> 3391.6089 | AG17: =+AE17+AF17 -> 24589.164
A18: CAPITAL HUMANO | B18: 0 | C18: 0 | D18: =+(B18+C18)*$D$16 -> 0 | E18: =+B18+D18+C18 -> 0 | F18: =+E18*16% -> 0 | G18: =+E18+F18 -> 0 | N18: CONSTRUCCIÓN | O18: =+SHARK!H17 -> 11948.64 | P18: =+SHARK!X17 -> 3655.6556 | Q18: =+(O18+P18)*$D$16 -> 468.12887 | R18: =+O18+Q18+P18 -> 16072.424 | S18: =+R18*16% -> 2571.5879 | T18: =+R18+S18 -> 18644.012
A19: CONTABILIDAD | B19: =+'LUXIMIA '!H16+'LUXIMIA '!H17+'LUXIMIA '!H28+'LUXIMIA '!H29+'LUXIMIA '!H32 -> 43811.68 | C19: =+'LUXIMIA '!V16+'LUXIMIA '!V17+'LUXIMIA '!V28+'LUXIMIA '!V29+'LUXIMIA '!V32 -> 13906.217 | D19: =+(B19+C19)*$D$16 -> 1731.5369 | E19: =+B19+D19+C19 -> 59449.434 | F19: =+E19*16% -> 9511.9095 | G19: =+E19+F19 -> 68961.344 | N19: COSTOS | O19: =+SHARK!H16 -> 15931.52 | P19: =+SHARK!X16 -> 4748.6308 | Q19: =+(O19+P19)*$D$16 -> 620.40452 | R19: =+O19+Q19+P19 -> 21300.555 | S19: =+R19*16% -> 3408.0889 | T19: =+R19+S19 -> 24708.644
A20: DIRECCIÓN CONSEJO | B20: =+'LUXIMIA '!H18+'LUXIMIA '!H24+'LUXIMIA '!H25+'LUXIMIA '!H26 -> 43811.68 | C20: =+'LUXIMIA '!V18+'LUXIMIA '!V24+'LUXIMIA '!V25+'LUXIMIA '!V26 -> 13529.567 | D20: =+(B20+C20)*$D$16 -> 1720.2374 | E20: =+B20+D20+C20 -> 59061.485 | F20: =+E20*16% -> 9449.8375 | G20: =+E20+F20 -> 68511.322 | N20: MANSION | P20: 0 | Q20: =+(O20+P20)*$D$16 -> 0 | R20: =+O20+Q20+P20 -> 0 | S20: =+R20*16% -> 0 | T20: =+R20+S20 -> 0 | AB20: =AB17 -> 15931.52 | AC20: =SUM(AC17:AC18) -> 4648.6308 | AD20: =SUM(AD17:AD18) -> 617.40452 | AE20: =SUM(AE17:AE18) -> 21197.555 | AF20: =SUM(AF17:AF18) -> 3391.6089 | AG20: =SUM(AG17:AG18) -> 24589.164
A21: JURIDICO | B21: =+'LUXIMIA '!H20+'LUXIMIA '!H22+'LUXIMIA '!H23+'LUXIMIA '!H33 -> 43811.68 | C21: =+'LUXIMIA '!V20+'LUXIMIA '!V22+'LUXIMIA '!V23+'LUXIMIA '!V33 -> 13529.497 | D21: =+(B21+C21)*$D$16 -> 1720.2353 | E21: =+B21+D21+C21 -> 59061.413 | F21: =+E21*16% -> 9449.826 | G21: =+E21+F21 -> 68511.239 | N21: MERCADOTECNIA | O21: 0 | P21: 0 | Q21: =+(O21+P21)*$D$16 -> 0 | R21: =+O21+Q21+P21 -> 0 | S21: =+R21*16% -> 0 | T21: =+R21+S21 -> 0
A22: FINANZAS | B22: =+'LUXIMIA '!H31+'LUXIMIA '!H35 -> 27880.16 | C22: =+'LUXIMIA '!V31+'LUXIMIA '!V35 -> 8404.2164 | D22: =+(B22+C22)*$D$16 -> 1088.5313 | E22: =+B22+D22+C22 -> 37372.908 | F22: =+E22*16% -> 5979.6652 | G22: =+E22+F22 -> 43352.573 | N22: POSTVENTA | O22: =+SHARK!H18+SHARK!H20 -> 15931.52 | P22: =+SHARK!X18+SHARK!X20 -> 5125.2808 | Q22: =+(O22+P22)*$D$16 -> 631.70402 | R22: =+O22+Q22+P22 -> 21688.505 | S22: =+R22*16% -> 3470.1608 | T22: =+R22+S22 -> 25158.666
A23: SEGURIDAD | B23: =+'LUXIMIA '!H21 -> 7965.76 | C23: ='LUXIMIA '!V21 -> 2562.6404 | D23: =+(B23+C23)*$D$16 -> 315.85201 | E23: =+B23+D23+C23 -> 10844.252 | F23: =+E23*16% -> 1735.0804 | G23: =+E23+F23 -> 12579.333 | N23: VENTAS | O23: =+SHARK!H19 -> 7965.76 | P23: =+SHARK!X19 -> 2562.6404 | Q23: =+(O23+P23)*$D$16 -> 315.85201 | R23: =+O23+Q23+P23 -> 10844.252 | S23: =+R23*16% -> 1735.0804 | T23: =+R23+S23 -> 12579.333
A24: SISTEMAS | B24: =+'LUXIMIA '!H19 -> 11948.64 | C24: =+'LUXIMIA '!V19 -> 3655.6556 | D24: =+(B24+C24)*$D$16 -> 468.12887 | E24: =+B24+D24+C24 -> 16072.424 | F24: =+E24*16% -> 2571.5879 | G24: =+E24+F24 -> 18644.012 | N24: FINIQUITO | O24: 0 | P24: 0 | Q24: =+(O24+P24)*$D$16 -> 0 | R24: =+O24+Q24+P24 -> 0 | S24: =+R24*16% -> 0 | T24: =+R24+S24 -> 0 | AF24: TOTAL NOMINA | AG24: =+AG20 -> 24589.164
A25: ZEN GARDENS | B25: =+'LUXIMIA '!H37 -> 7965.76 | C25: =+'LUXIMIA '!V37 -> 2562.6404 | D25: =+(B25+C25)*$D$16 -> 315.85201 | E25: =+B25+D25+C25 -> 10844.252 | F25: =+E25*16% -> 1735.0804 | G25: =+E25+F25 -> 12579.333 | AF25: FINIQUITO | AG25: 0
A26: AUDITORIA | B26: =+'LUXIMIA '!H30 -> 7965.76 | C26: =+'LUXIMIA '!V30 -> 2562.6404 | D26: =+(B26+C26)*$D$16 -> 315.85201 | E26: =+B26+D26+C26 -> 10844.252 | F26: =+E26*16% -> 1735.0804 | G26: =+E26+F26 -> 12579.333 | AF26: GRAN TOTAL | AG26: =+AG24+AG25 -> 24589.164
A27: TESORERIA | B27: =+'LUXIMIA '!H27+'LUXIMIA '!H34 -> 15931.52 | C27: ='LUXIMIA '!V27+'LUXIMIA '!V34 -> 5125.2808 | D27: =+(B27+C27)*$D$16 -> 631.70402 | E27: =+B27+D27+C27 -> 21688.505 | F27: =+E27*16% -> 3470.1608 | G27: =+E27+F27 -> 25158.666
A28: FINIQUITO | D28: =+(B28+C28)*$D$16 -> 0 | E28: =+B28+D28+C28 -> 0 | F28: =+E28*16% -> 0 | G28: =+E28+F28 -> 0 | O28: =O17+O18+O19+O20+O21+O22+O23+O24 -> 59743.2 | P28: =SUM(P17:P25) -> 18654.848 | Q28: =SUM(Q17:Q25) -> 2351.9414 | R28: =SUM(R17:R25) -> 80749.989 | S28: =SUM(S17:S25) -> 12919.998 | T28: =SUM(T17:T25) -> 93669.988
C29: 0 | D29: =+(B29+C29)*$D$16 -> 0 | E29: =+B29+D29+C29 -> 0 | F29: =+E29*16% -> 0 | G29: =+E29+F29 -> 0 | P29: =+P28-SHARK!X22 -> -2562.6404 | T29: =+T28-SHARK!AE26 -> -12579.333
B30: =SUM(B17:B29) -> 231007.04 | C30: =SUM(C17:C29) -> 71679.932 | D30: =SUM(D17:D29) -> 9080.6091 | E30: =SUM(E17:E29) -> 311767.58 | F30: =SUM(F17:F29) -> 49882.813 | G30: =SUM(G17:G29)+G34 -> 361650.39 | AB30: FINIQUITO
G31: =G30-'LUXIMIA '!AC43 -> -43636.685
S32: TOTAL NOMINA | T32: =+T28 -> 93669.988
S33: FINIQUITO | AB33: TOTAL FINIQUITO | AC33: COMISIÓN | AD33: SUBTOTAL | AE33: IVA | AF33: TOTAL | AG33: TOTAL
S34: GRAN TOTAL | T34: =+T32+T33 -> 93669.988 | U34: =+T34-SHARK!AE26 -> -12579.333
F35: GRAN TOTAL | G35: =G30+G43 -> 361650.39 | T35: =+T34-SHARK!AE26 -> -12579.333 | AC35: =+AB35*$D$16 -> 0 | AD35: =+AC35+AB35 -> 0 | AE35: =+AD35*16% -> 0 | AF35: =+AD35+AE35 -> 0 | AG35: =AF35 -> 0
AC36: =+AB36*$D$16 -> 0 | AD36: =+AC36+AB36 -> 0 | AE36: =+AD36*16% -> 0 | AF36: =+AD36+AE36 -> 0 | AG36: =+AF36 -> 0
O37: FINIQUITO | AC37: =+AB37*$D$16 -> 0 | AD37: =+AC37+AB37 -> 0 | AE37: =+AD37*16% -> 0 | AF37: =+AD37+AE37 -> 0 | AG37: =+AF37 -> 0
A38: FINIQUITO | AB38: =SUM(AB35:AB37) -> 0 | AC38: =SUM(AC35:AC37) -> 0 | AD38: =SUM(AD35:AD37) -> 0 | AE38: =SUM(AE35:AE37) -> 0 | AF38: =SUM(AF35:AF37) -> 0 | AG38: =SUM(AG35:AG37) -> 0
B39: TOTAL FINIQUITO | C39: COMISIÓN | D39: SUBTOTAL | E39: IVA | F39: TOTAL | G39: TOTAL
O40: TOTAL FINIQUITO | P40: COMISIÓN | Q40: SUBTOTAL | R40: IVA | S40: TOTAL | T40: TOTAL
C41: =+B41*$D$16 -> 0 | D41: =+C41+B41 -> 0 | E41: =+D41*16% -> 0 | F41: =+D41+E41 -> 0 | G41: =+F41 -> 0
C42: =+B42*$D$16 -> 0 | D42: =+C42+B42 -> 0 | E42: =+D42*16% -> 0 | F42: =+D42+E42 -> 0 | G42: =+F42 -> 0 | P42: =+O42*3% -> 0 | Q42: =+O42+P42 -> 0 | R42: =+Q42*16% -> 0 | S42: =+Q42+R42 -> 0 | T42: =+S42 -> 0
B43: =SUM(B40:B42) -> 0 | C43: =SUM(C40:C42) -> 0 | D43: =SUM(D40:D42) -> 0 | E43: =SUM(E40:E42) -> 0 | F43: =SUM(F40:F42) -> 0 | G43: =SUM(G40:G42) -> 0 | P43: =+O43*3% -> 0 | Q43: =+O43+P43 -> 0 | R43: =+Q43*16% -> 0 | S43: =+Q43+R43 -> 0 | T43: =+S43 -> 0
P44: =+O44*$D$16 -> 0 | Q44: =+P44+O44 -> 0 | R44: =+Q44*16% -> 0 | S44: =+Q44+R44 -> 0 | T44: =+S44 -> 0
O45: =SUM(O42:O44) -> 0 | P45: =SUM(P42:P44) -> 0 | Q45: =SUM(Q42:Q44) -> 0 | R45: =SUM(R42:R44) -> 0 | S45: =SUM(S42:S44) -> 0 | T45: =SUM(T42:T44) -> 0

Sheet RESUMEN
A2: TOTAL NOMINA FISCAL
B3: "NOMINA LUXIMIA"
B4: =+'LUXIMIA '!A11 -> 02. DEL 16-31 ENERO 2025
B6: NOMINA FISCAL | C6: COSTO SOCIAL | D6: 0.03 | E6: SUBTOTAL | F6: IVA | G6: TOTAL
A7: LUXIMIA | B7: =+'LUXIMIA '!L43 -> 258504.96 | C7: =+'LUXIMIA '!V43 -> 80704.178 | D7: =+(B7+C7)*$D$6 -> 10176.274 | E7: =+B7+D7+C7 -> 349385.41 | F7: =E7*16% -> 55901.666 | G7: =E7+F7 -> 405287.08
A8: FINIQUITO | B8: 0 | C8: 0 | D8: =+(B8+C8)*$D$6 -> 0 | E8: =+B8+D8+C8 -> 0 | F8: =E8*16% -> 0 | G8: =E8+F8 -> 0
A9: SHARK | B9: =SHARK!N22 -> 67708.96 | C9: =+SHARK!X22-RESUMEN!C8 -> 21217.488 | D9: =+(B9+C9)*$D$6 -> 2667.7935 | E9: =+B9+D9+C9 -> 91594.242 | F9: =E9*16% -> 14655.079 | G9: =E9+F9 -> 106249.32
A10: PETREO | B10: =PETREOS!L16 -> 18420.82 | C10: =PETREOS!U16 -> 5418.5628 | D10: =+(B10+C10)*$D$6 -> 715.18148 | E10: =+B10+D10+C10 -> 24554.564 | F10: =E10*16% -> 3928.7303 | G10: =E10+F10 -> 28483.295
B11: =SUM(B7:B10) -> 344634.74 | C11: =SUM(C7:C10) -> 107340.23 | D11: =SUM(D7:D10) -> 13559.249 | E11: =SUM(E7:E10) -> 465534.22 | F11: =SUM(F7:F10) -> 74485.475 | G11: =SUM(G7:G10) -> 540019.69
F13: TOTAL | G13: =G11 -> 540019.69
A18: RESUMEN
A19: TOTAL PERCEPCIONES | B19: =+B7+B8+B9+B10 -> 344634.74
A20: RETENCION ISR
A21: COSTO SOCIAL (IMSS, INFONAVIT, RCV, ISN) | B21: =+C7+C9+C8+C10 -> 107340.23
A22: COMISION | B22: =(+B19+B21+B20)*3% -> 13559.249
A23: BASE DE FACTURACION | B23: =+B19+B21+B22+B20 -> 465534.22
A24: IVA | B24: =+B23*16% -> 74485.475
A25: FINIQUITOS | B25: =+B8 -> 0
A27: TOTAL NOMINA | B27: =+B23+B24 -> 540019.69
A28: TOTAL FACTURACION | B28: =+B27-B26 -> 540019.69

Sheet Cuotas IMSS
K1: UMA | L1: 103.74 | O1: =+L1*25 -> 2593.5 | P1: =+O1/1.0493 -> 2471.6478
B2: °°°° RAMAS DE COSTO SOCIALES 2023°°°°° | H2: 1.0493 | K2: 3 UMAS | L2: =+L1*3 -> 311.22
J3: EXCEDENTE (3 UMAS)
I6: 20.4 | J6: 0.4 | K6: 1.1 | L6: 0.25 | M6: 0.7 | N6: 0.375 | O6: 1.05 | Q6: 0.625 | R6: 1.75 | S6: 1 | T6: 2 | U6: 1.125 | X6: 5 | Z6: MENSUAL | AC6: BIMESTRE
B7: DIAS DEL MES | C7: DIAS ANTERIORES | D7: FALTAS / PERMISOS S/GOCE/ SUSPENSION | E7: INCAPACIDADES | F7: TOTAL DIAS MENSUALES | G7: SD | H7: SDI | I7: CF | J7: EXC TRAB | K7: EXC PATR | L7: PD TRAB | M7: PD PATR | N7: GMP TRA | O7: GMP PATR | P7: RT | Q7: IV TRAB | R7: IV PATR | S7: GPS | T7: SAR | U7: CV TRAB | V7: PORCENTAJE | W7: CV PATR | X7: INFONAVIT | Z7: PATRON | AA7: OBRERRA | AB7: DESCUENTO IMSS TRABAJADOR | AC7: RCV | AD7: OBRERRA | AE7: TOTAL / COBRADO EN SISTEMA | AG7: PRIMA DE RIESGO | AI7: COSTO | AJ7: RCV | AK7: INFONAVIT | AP7: RAMAS DE CENSATIA SMG 2023 | AU7: RAMAS DE CENSATIA UMA 2023
F8: 15 | G8: 1037.2 | H8: =+G8*$H$2 -> 1088.334 | I8: =ROUND((($F8)*$L$1*($I$6/100)),2) -> 317.44 | J8: =ROUND(IF($H8<$L$2,0,(($F8)*($H8-$L$2))*($J$6/100)),2) -> 46.63 | K8: =ROUND(IF($H8<$L$2,0,(($F8)*($H8-$L$2))*($K$6/100)),2) -> 128.22 | L8: =ROUND(($H8*($F8)*($L$6/100)),2) -> 40.81 | M8: =ROUND(($H8*($F8)*($M$6/100)),2) -> 114.28 | N8: =ROUND(($H8*($F8)*($N$6/100)),2) -> 61.22 | O8: =ROUND(($H8*($F8)*($O$6/100)),2) -> 171.41 | P8: =ROUND(($H8*($F8)*($AG8)),2) -> 81.63 | Q8: =$H8*($F8)*($Q$6/100) -> 102.03131 | R8: =$H8*($F8)*($R$6/100) -> 285.68766 | S8: =ROUND(($H8*(F8)*($S$6/100)),2) -> 163.25 | T8: =ROUND(($H8*($F8)*($T$6/100)),2) -> 326.5 | U8: =ROUND(($H8*($F8)*($U$6/100)),2) -> 183.66 | V8: =+IFERROR(LOOKUP($G8,$AU$8:$AW$15,$AW$8:$AW$15),0) -> 4.241 | W8: =ROUND(($H8*($F8)*($V$8/100)),2) -> 692.34 | X8: =ROUND(($H8*($F8)*($X$6/100)),2) -> 816.25 | Z8: =+I8+K8+M8+O8+P8+R8+S8 -> 1261.9177 | AA8: =+J8+L8+N8+Q8 -> 250.69131 | AB8: =+U8+AA8 -> 434.35131 | AC8: =+W8+T8+U8 -> 1202.5 | AD8: =+X8 -> 816.25 | AE8: =+SUM(Z8:AD8)-AB8-AA8 -> 3280.6677 | AG8: 0.005 | AI8: =+Z8 -> 1261.9177 | AJ8: =+W8+T8 -> 1018.84 | AK8: =+X8 -> 816.25 | AL8: =+AI8+AJ8+AK8-AE8 -> -183.66 | AM8: 457.06 | AN8: =+AI8+AJ8+AK8-AM8 -> 2639.9477 | AP8: 207.44 | AQ8: 209.49 | AR8: 3.15 | AU8: 96.22 | AV8: 97.1722 | AW8: 3.15
F9: 15 | G9: 414.88 | H9: =+G9*$H$2 -> 435.33358 | I9: =ROUND((($F9)*$L$1*($I$6/100)),2) -> 317.44 | J9: =ROUND(IF($H9<$L$2,0,(($F9)*($H9-$L$2))*($J$6/100)),2) -> 7.45 | K9: =ROUND(IF($H9<$L$2,0,(($F9)*($H9-$L$2))*($K$6/100)),2) -> 20.48 | L9: =ROUND(($H9*($F9)*($L$6/100)),2) -> 16.33 | M9: =ROUND(($H9*($F9)*($M$6/100)),2) -> 45.71 | N9: =ROUND(($H9*($F9)*($N$6/100)),2) -> 24.49 | O9: =ROUND(($H9*($F9)*($O$6/100)),2) -> 68.57 | P9: =ROUND(($H9*($F9)*($AG9)),2) -> 32.65 | Q9: =$H9*($F9)*($Q$6/100) -> 40.812523 | R9: =$H9*($F9)*($R$6/100) -> 114.27507 | S9: =ROUND(($H9*(F9)*($S$6/100)),2) -> 65.3 | T9: =ROUND(($H9*($F9)*($T$6/100)),2) -> 130.6 | U9: =ROUND(($H9*($F9)*($U$6/100)),2) -> 73.46 | V9: =+IFERROR(LOOKUP($G9,$AU$8:$AW$15,$AW$8:$AW$15),0) -> 4.241 | W9: =ROUND(($H9*($F9)*($V$8/100)),2) -> 276.94 | X9: =ROUND(($H9*($F9)*($X$6/100)),2) -> 326.5 | Z9: =+I9+K9+M9+O9+P9+R9+S9 -> 664.42507 | AA9: =+J9+L9+N9+Q9 -> 89.082523 | AB9: =+U9+AA9 -> 162.54252 | AC9: =+W9+T9 -> 407.54 | AD9: =+X9 -> 326.5 | AE9: =+SUM(Z9:AD9)-AB9-AA9 -> 1398.4651 | AG9: 0.005 | AI9: =+Z9 -> 664.42507 | AJ9: =+W9+T9 -> 407.54 | AK9: =+X9 -> 326.5 | AL9: =+AI9+AJ9+AK9-AE9 -> 0 | AP9: 209.5144 | AQ9: 311.16 | AR9: 3.281 | AU9: 97.1822 | AV9: 144.33 | AW9: 3.281
F10: 15 | G10: 414.88 | H10: =+G10*$H$2 -> 435.33358 | I10: =ROUND((($F10)*$L$1*($I$6/100)),2) -> 317.44 | J10: =ROUND(IF($H10<$L$2,0,(($F10)*($H10-$L$2))*($J$6/100)),2) -> 7.45 | K10: =ROUND(IF($H10<$L$2,0,(($F10)*($H10-$L$2))*($K$6/100)),2) -> 20.48 | L10: =ROUND(($H10*($F10)*($L$6/100)),2) -> 16.33 | M10: =ROUND(($H10*($F10)*($M$6/100)),2) -> 45.71 | N10: =ROUND(($H10*($F10)*($N$6/100)),2) -> 24.49 | O10: =ROUND(($H10*($F10)*($O$6/100)),2) -> 68.57 | P10: =ROUND(($H10*($F10)*($AG10)),2) -> 32.65 | Q10: =$H10*($F10)*($Q$6/100) -> 40.812523 | R10: =$H10*($F10)*($R$6/100) -> 114.27507 | S10: =ROUND(($H10*(F10)*($S$6/100)),2) -> 65.3 | T10: =ROUND(($H10*($F10)*($T$6/100)),2) -> 130.6 | U10: =ROUND(($H10*($F10)*($U$6/100)),2) -> 73.46 | V10: =+IFERROR(LOOKUP($G10,$AU$8:$AW$15,$AW$8:$AW$15),0) -> 4.241 | W10: =ROUND(($H10*($F10)*($V$8/100)),2) -> 276.94 | X10: =ROUND(($H10*($F10)*($X$6/100)),2) -> 326.5 | Z10: =+I10+K10+M10+O10+P10+R10+S10 -> 664.42507 | AA10: =+J10+L10+N10+Q10 -> 89.082523 | AB10: =+U10+AA10 -> 162.54252 | AC10: =+W10+T10 -> 407.54 | AD10: =+X10 -> 326.5 | AE10: =+SUM(Z10:AD10)-AB10-AA10 -> 1398.4651 | AG10: 0.005 | AI10: =+Z10 -> 664.42507 | AJ10: =+W10+T10 -> 407.54 | AK10: =+X10 -> 326.5 | AL10: =+AI10+AJ10+AK10-AE10 -> 0 | AP10: 313.2344 | AQ10: 414.88 | AR10: 3.575 | AU10: 145.2922 | AV10: 192.44 | AW10: 3.575
F11: 15 | G11: 622.33 | H11: =+G11*$H$2 -> 653.01087 | I11: =ROUND((($F11)*$L$1*($I$6/100)),2) -> 317.44 | J11: =ROUND(IF($H11<$L$2,0,(($F11)*($H11-$L$2))*($J$6/100)),2) -> 20.51 | K11: =ROUND(IF($H11<$L$2,0,(($F11)*($H11-$L$2))*($K$6/100)),2) -> 56.4 | L11: =ROUND(($H11*($F11)*($L$6/100)),2) -> 24.49 | M11: =ROUND(($H11*($F11)*($M$6/100)),2) -> 68.57 | N11: =ROUND(($H11*($F11)*($N$6/100)),2) -> 36.73 | O11: =ROUND(($H11*($F11)*($O$6/100)),2) -> 102.85 | P11: =ROUND(($H11*($F11)*($AG11)),2) -> 48.98 | Q11: =$H11*($F11)*($Q$6/100) -> 61.219769 | R11: =$H11*($F11)*($R$6/100) -> 171.41535 | S11: =ROUND(($H11*(F11)*($S$6/100)),2) -> 97.95 | T11: =ROUND(($H11*($F11)*($T$6/100)),2) -> 195.9 | U11: =ROUND(($H11*($F11)*($U$6/100)),2) -> 110.2 | V11: =+IFERROR(LOOKUP($G11,$AU$8:$AW$15,$AW$8:$AW$15),0) -> 4.241 | W11: =ROUND(($H11*($F11)*($V$8/100)),2) -> 415.41 | X11: =ROUND(($H11*($F11)*($X$6/100)),2) -> 489.76 | Z11: =+I11+K11+M11+O11+P11+R11+S11 -> 863.60535 | AA11: =+J11+L11+N11+Q11 -> 142.94977 | AB11: =+U11+AA11 -> 253.14977 | AC11: =+W11+T11 -> 611.31 | AD11: =+X11 -> 489.76 | AE11: =+SUM(Z11:AD11)-AB11-AA11 -> 1964.6754 | AG11: 0.005 | AI11: =+Z11 -> 863.60535 | AJ11: =+W11+T11 -> 611.31 | AK11: =+X11 -> 489.76 | AL11: =+AI11+AJ11+AK11-AE11 -> 0 | AP11: 416.9544 | AQ11: 518.6 | AR11: 3.751 | AU11: 193.4022 | AV11: 240.55 | AW11: 3.751
F12: 15 | G12: 414.88 | H12: =+G12*$H$2 -> 435.33358 | I12: =ROUND((($F12)*$L$1*($I$6/100)),2) -> 317.44 | J12: =ROUND(IF($H12<$L$2,0,(($F12)*($H12-$L$2))*($J$6/100)),2) -> 7.45 | K12: =ROUND(IF($H12<$L$2,0,(($F12)*($H12-$L$2))*($K$6/100)),2) -> 20.48 | L12: =ROUND(($H12*($F12)*($L$6/100)),2) -> 16.33 | M12: =ROUND(($H12*($F12)*($M$6/100)),2) -> 45.71 | N12: =ROUND(($H12*($F12)*($N$6/100)),2) -> 24.49 | O12: =ROUND(($H12*($F12)*($O$6/100)),2) -> 68.57 | P12: =ROUND(($H12*($F12)*($AG12)),2) -> 32.65 | Q12: =$H12*($F12)*($Q$6/100) -> 40.812523 | R12: =$H12*($F12)*($R$6/100) -> 114.27507 | S12: =ROUND(($H12*(F12)*($S$6/100)),2) -> 65.3 | T12: =ROUND(($H12*($F12)*($T$6/100)),2) -> 130.6 | U12: =ROUND(($H12*($F12)*($U$6/100)),2) -> 73.46 | V12: =+IFERROR(LOOKUP($G12,$AU$8:$AW$15,$AW$8:$AW$15),0) -> 4.241 | W12: =ROUND(($H12*($F12)*($V$8/100)),2) -> 276.94 | X12: =ROUND(($H12*($F12)*($X$6/100)),2) -> 326.5 | Z12: =+I12+K12+M12+O12+P12+R12+S12 -> 664.42507 | AA12: =+J12+L12+N12+Q12 -> 89.082523 | AB12: =+U12+AA12 -> 162.54252 | AC12: =+W12+T12 -> 407.54 | AD12: =+X12 -> 326.5 | AE12: =+SUM(Z12:AD12)-AB12-AA12 -> 1398.4651 | AG12: 0.005 | AI12: =+Z12 -> 664.42507 | AJ12: =+W12+T12 -> 407.54 | AK12: =+X12 -> 326.5 | AL12: =+AI12+AJ12+AK12-AE12 -> 0 | AP12: 520.6744 | AQ12: 622.32 | AR12: 3.869 | AU12: 241.5122 | AV12: 288.66 | AW12: 3.869
F13: 15 | G13: 414.88 | H13: =+G13*$H$2 -> 435.33358 | I13: =ROUND((($F13)*$L$1*($I$6/100)),2) -> 317.44 | J13: =ROUND(IF($H13<$L$2,0,(($F13)*($H13-$L$2))*($J$6/100)),2) -> 7.45 | K13: =ROUND(IF($H13<$L$2,0,(($F13)*($H13-$L$2))*($K$6/100)),2) -> 20.48 | L13: =ROUND(($H13*($F13)*($L$6/100)),2) -> 16.33 | M13: =ROUND(($H13*($F13)*($M$6/100)),2) -> 45.71 | N13: =ROUND(($H13*($F13)*($N$6/100)),2) -> 24.49 | O13: =ROUND(($H13*($F13)*($O$6/100)),2) -> 68.57 | P13: =ROUND(($H13*($F13)*($AG13)),2) -> 32.65 | Q13: =$H13*($F13)*($Q$6/100) -> 40.812523 | R13: =$H13*($F13)*($R$6/100) -> 114.27507 | S13: =ROUND(($H13*(F13)*($S$6/100)),2) -> 65.3 | T13: =ROUND(($H13*($F13)*($T$6/100)),2) -> 130.6 | U13: =ROUND(($H13*($F13)*($U$6/100)),2) -> 73.46 | V13: =+IFERROR(LOOKUP($G13,$AU$8:$AW$15,$AW$8:$AW$15),0) -> 4.241 | W13: =ROUND(($H13*($F13)*($V$8/100)),2) -> 276.94 | X13: =ROUND(($H13*($F13)*($X$6/100)),2) -> 326.5 | Z13: =+I13+K13+M13+O13+P13+R13+S13 -> 664.42507 | AA13: =+J13+L13+N13+Q13 -> 89.082523 | AB13: =+U13+AA13 -> 162.54252 | AC13: =+W13+T13 -> 407.54 | AD13: =+X13 -> 326.5 | AE13: =+SUM(Z13:AD13)-AB13-AA13 -> 1398.4651 | AG13: 0.005 | AI13: =+Z13 -> 664.42507 | AJ13: =+W13+T13 -> 407.54 | AK13: =+X13 -> 326.5 | AL13: =+AI13+AJ13+AK13-AE13 -> 0 | AP13: 624.3944 | AQ13: 726.04 | AR13: 3.953 | AU13: 289.6222 | AV13: 336.77 | AW13: 3.953
F14: 15 | G14: 1037.2 | H14: =+G14*$H$2 -> 1088.334 | I14: =ROUND((($F14)*$L$1*($I$6/100)),2) -> 317.44 | J14: =ROUND(IF($H14<$L$2,0,(($F14)*($H14-$L$2))*($J$6/100)),2) -> 46.63 | K14: =ROUND(IF($H14<$L$2,0,(($F14)*($H14-$L$2))*($K$6/100)),2) -> 128.22 | L14: =ROUND(($H14*($F14)*($L$6/100)),2) -> 40.81 | M14: =ROUND(($H14*($F14)*($M$6/100)),2) -> 114.28 | N14: =ROUND(($H14*($F14)*($N$6/100)),2) -> 61.22 | O14: =ROUND(($H14*($F14)*($O$6/100)),2) -> 171.41 | P14: =ROUND(($H14*($F14)*($AG14)),2) -> 81.63 | Q14: =$H14*($F14)*($Q$6/100) -> 102.03131 | R14: =$H14*($F14)*($R$6/100) -> 285.68766 | S14: =ROUND(($H14*(F14)*($S$6/100)),2) -> 163.25 | T14: =ROUND(($H14*($F14)*($T$6/100)),2) -> 326.5 | U14: =ROUND(($H14*($F14)*($U$6/100)),2) -> 183.66 | V14: =+IFERROR(LOOKUP($G14,$AU$8:$AW$15,$AW$8:$AW$15),0) -> 4.241 | W14: =ROUND(($H14*($F14)*($V$8/100)),2) -> 692.34 | X14: =ROUND(($H14*($F14)*($X$6/100)),2) -> 816.25 | Z14: =+I14+K14+M14+O14+P14+R14+S14 -> 1261.9177 | AA14: =+J14+L14+N14+Q14 -> 250.69131 | AB14: =+U14+AA14 -> 434.35131 | AC14: =+W14+T14 -> 1018.84 | AD14: =+X14 -> 816.25 | AE14: =+SUM(Z14:AD14)-AB14-AA14 -> 3097.0077 | AG14: 0.005 | AI14: =+Z14 -> 1261.9177 | AJ14: =+W14+T14 -> 1018.84 | AK14: =+X14 -> 816.25 | AL14: =+AI14+AJ14+AK14-AE14 -> 0 | AP14: 105.7944 | AQ14: 829.76 | AR14: 4.016 | AU14: 337.7322 | AV14: 384.88 | AW14: 4.016
F15: 15 | G15: 414.88 | H15: =+G15*$H$2 -> 435.33358 | I15: =ROUND((($F15)*$L$1*($I$6/100)),2) -> 317.44 | J15: =ROUND(IF($H15<$L$2,0,(($F15)*($H15-$L$2))*($J$6/100)),2) -> 7.45 | K15: =ROUND(IF($H15<$L$2,0,(($F15)*($H15-$L$2))*($K$6/100)),2) -> 20.48 | L15: =ROUND(($H15*($F15)*($L$6/100)),2) -> 16.33 | M15: =ROUND(($H15*($F15)*($M$6/100)),2) -> 45.71 | N15: =ROUND(($H15*($F15)*($N$6/100)),2) -> 24.49 | O15: =ROUND(($H15*($F15)*($O$6/100)),2) -> 68.57 | P15: =ROUND(($H15*($F15)*($AG15)),2) -> 32.65 | Q15: =$H15*($F15)*($Q$6/100) -> 40.812523 | R15: =$H15*($F15)*($R$6/100) -> 114.27507 | S15: =ROUND(($H15*(F15)*($S$6/100)),2) -> 65.3 | T15: =ROUND(($H15*($F15)*($T$6/100)),2) -> 130.6 | U15: =ROUND(($H15*($F15)*($U$6/100)),2) -> 73.46 | V15: =+IFERROR(LOOKUP($G15,$AU$8:$AW$15,$AW$8:$AW$15),0) -> 4.241 | W15: =ROUND(($H15*($F15)*($V$8/100)),2) -> 276.94 | X15: =ROUND(($H15*($F15)*($X$6/100)),2) -> 326.5 | Z15: =+I15+K15+M15+O15+P15+R15+S15 -> 664.42507 | AA15: =+J15+L15+N15+Q15 -> 89.082523 | AB15: =+U15+AA15 -> 162.54252 | AC15: =+W15+T15 -> 407.54 | AD15: =+X15 -> 326.5 | AE15: =+SUM(Z15:AD15)-AB15-AA15 -> 1398.4651 | AG15: 0.005 | AI15: =+Z15 -> 664.42507 | AJ15: =+W15+T15 -> 407.54 | AK15: =+X15 -> 326.5 | AL15: =+AI15+AJ15+AK15-AE15 -> 0 | AP15: 831.8344 | AQ15: en adelante | AR15: 4.241 | AU15: 385.8422 | AV15: en adelante | AW15: 4.241
F16: 15 | G16: 414.88 | H16: =+G16*$H$2 -> 435.33358 | I16: =ROUND((($F16)*$L$1*($I$6/100)),2) -> 317.44 | J16: =ROUND(IF($H16<$L$2,0,(($F16)*($H16-$L$2))*($J$6/100)),2) -> 7.45 | K16: =ROUND(IF($H16<$L$2,0,(($F16)*($H16-$L$2))*($K$6/100)),2) -> 20.48 | L16: =ROUND(($H16*($F16)*($L$6/100)),2) -> 16.33 | M16: =ROUND(($H16*($F16)*($M$6/100)),2) -> 45.71 | N16: =ROUND(($H16*($F16)*($N$6/100)),2) -> 24.49 | O16: =ROUND(($H16*($F16)*($O$6/100)),2) -> 68.57 | P16: =ROUND(($H16*($F16)*($AG16)),2) -> 32.65 | Q16: =$H16*($F16)*($Q$6/100) -> 40.812523 | R16: =$H16*($F16)*($R$6/100) -> 114.27507 | S16: =ROUND(($H16*(F16)*($S$6/100)),2) -> 65.3 | T16: =ROUND(($H16*($F16)*($T$6/100)),2) -> 130.6 | U16: =ROUND(($H16*($F16)*($U$6/100)),2) -> 73.46 | V16: =+IFERROR(LOOKUP($G16,$AU$8:$AW$15,$AW$8:$AW$15),0) -> 4.241 | W16: =ROUND(($H16*($F16)*($V$8/100)),2) -> 276.94 | X16: =ROUND(($H16*($F16)*($X$6/100)),2) -> 326.5 | Z16: =+I16+K16+M16+O16+P16+R16+S16 -> 664.42507 | AA16: =+J16+L16+N16+Q16 -> 89.082523 | AB16: =+U16+AA16 -> 162.54252 | AC16: =+W16+T16 -> 407.54 | AD16: =+X16 -> 326.5 | AE16: =+SUM(Z16:AD16)-AB16-AA16 -> 1398.4651 | AG16: 0.005 | AI16: =+Z16 -> 664.42507 | AJ16: =+W16+T16 -> 407.54 | AK16: =+X16 -> 326.5 | AL16: =+AI16+AJ16+AK16-AE16 -> 0
F17: 15 | G17: 829.76 | H17: =+G17*$H$2 -> 870.66717 | I17: =ROUND((($F17)*$L$1*($I$6/100)),2) -> 317.44 | J17: =ROUND(IF($H17<$L$2,0,(($F17)*($H17-$L$2))*($J$6/100)),2) -> 33.57 | K17: =ROUND(IF($H17<$L$2,0,(($F17)*($H17-$L$2))*($K$6/100)),2) -> 92.31 | L17: =ROUND(($H17*($F17)*($L$6/100)),2) -> 32.65 | M17: =ROUND(($H17*($F17)*($M$6/100)),2) -> 91.42 | N17: =ROUND(($H17*($F17)*($N$6/100)),2) -> 48.98 | O17: =ROUND(($H17*($F17)*($O$6/100)),2) -> 137.13 | P17: =ROUND(($H17*($F17)*($AG17)),2) -> 65.3 | Q17: =$H17*($F17)*($Q$6/100) -> 81.625047 | R17: =$H17*($F17)*($R$6/100) -> 228.55013 | S17: =ROUND(($H17*(F17)*($S$6/100)),2) -> 130.6 | T17: =ROUND(($H17*($F17)*($T$6/100)),2) -> 261.2 | U17: =ROUND(($H17*($F17)*($U$6/100)),2) -> 146.93 | V17: =+IFERROR(LOOKUP($G17,$AU$8:$AW$15,$AW$8:$AW$15),0) -> 4.241 | W17: =ROUND(($H17*($F17)*($V$8/100)),2) -> 553.87 | X17: =ROUND(($H17*($F17)*($X$6/100)),2) -> 653 | Z17: =+I17+K17+M17+O17+P17+R17+S17 -> 1062.7501 | AA17: =+J17+L17+N17+Q17 -> 196.82505 | AB17: =+U17+AA17 -> 343.75505 | AC17: =+W17+T17 -> 815.07 | AD17: =+X17 -> 653 | AE17: =+SUM(Z17:AD17)-AB17-AA17 -> 2530.8201 | AG17: 0.005 | AI17: =+Z17 -> 1062.7501 | AJ17: =+W17+T17 -> 815.07 | AK17: =+X17 -> 653 | AL17: =+AI17+AJ17+AK17-AE17 -> 0
F18: 15 | G18: 622.32 | H18: =+G18*$H$2 -> 653.00038 | I18: =ROUND((($F18)*$L$1*($I$6/100)),2) -> 317.44 | J18: =ROUND(IF($H18<$L$2,0,(($F18)*($H18-$L$2))*($J$6/100)),2) -> 20.51 | K18: =ROUND(IF($H18<$L$2,0,(($F18)*($H18-$L$2))*($K$6/100)),2) -> 56.39 | L18: =ROUND(($H18*($F18)*($L$6/100)),2) -> 24.49 | M18: =ROUND(($H18*($F18)*($M$6/100)),2) -> 68.57 | N18: =ROUND(($H18*($F18)*($N$6/100)),2) -> 36.73 | O18: =ROUND(($H18*($F18)*($O$6/100)),2) -> 102.85 | P18: =ROUND(($H18*($F18)*($AG18)),2) -> 48.98 | Q18: =$H18*($F18)*($Q$6/100) -> 61.218785 | R18: =$H18*($F18)*($R$6/100) -> 171.4126 | S18: =ROUND(($H18*(F18)*($S$6/100)),2) -> 97.95 | T18: =ROUND(($H18*($F18)*($T$6/100)),2) -> 195.9 | U18: =ROUND(($H18*($F18)*($U$6/100)),2) -> 110.19 | V18: =+IFERROR(LOOKUP($G18,$AU$8:$AW$15,$AW$8:$AW$15),0) -> 4.241 | W18: =ROUND(($H18*($F18)*($V$8/100)),2) -> 415.41 | X18: =ROUND(($H18*($F18)*($X$6/100)),2) -> 489.75 | Z18: =+I18+K18+M18+O18+P18+R18+S18 -> 863.5926 | AA18: =+J18+L18+N18+Q18 -> 142.94879 | AB18: =+U18+AA18 -> 253.13879 | AC18: =+W18+T18 -> 611.31 | AD18: =+X18 -> 489.75 | AE18: =+SUM(Z18:AD18)-AB18-AA18 -> 1964.6526 | AG18: 0.005 | AI18: =+Z18 -> 863.5926 | AJ18: =+W18+T18 -> 611.31 | AK18: =+X18 -> 489.75 | AL18: =+AI18+AJ18+AK18-AE18 -> 0
F19: 15 | G19: 622.33 | H19: =+G19*$H$2 -> 653.01087 | I19: =ROUND((($F19)*$L$1*($I$6/100)),2) -> 317.44 | J19: =ROUND(IF($H19<$L$2,0,(($F19)*($H19-$L$2))*($J$6/100)),2) -> 20.51 | K19: =ROUND(IF($H19<$L$2,0,(($F19)*($H19-$L$2))*($K$6/100)),2) -> 56.4 | L19: =ROUND(($H19*($F19)*($L$6/100)),2) -> 24.49 | M19: =ROUND(($H19*($F19)*($M$6/100)),2) -> 68.57 | N19: =ROUND(($H19*($F19)*($N$6/100)),2) -> 36.73 | O19: =ROUND(($H19*($F19)*($O$6/100)),2) -> 102.85 | P19: =ROUND(($H19*($F19)*($AG19)),2) -> 48.98 | Q19: =$H19*($F19)*($Q$6/100) -> 61.219769 | R19: =$H19*($F19)*($R$6/100) -> 171.41535 | S19: =ROUND(($H19*(F19)*($S$6/100)),2) -> 97.95 | T19: =ROUND(($H19*($F19)*($T$6/100)),2) -> 195.9 | U19: =ROUND(($H19*($F19)*($U$6/100)),2) -> 110.2 | V19: =+IFERROR(LOOKUP($G19,$AU$8:$AW$15,$AW$8:$AW$15),0) -> 4.241 | W19: =ROUND(($H19*($F19)*($V$8/100)),2) -> 415.41 | X19: =ROUND(($H19*($F19)*($X$6/100)),2) -> 489.76 | Z19: =+I19+K19+M19+O19+P19+R19+S19 -> 863.60535 | AA19: =+J19+L19+N19+Q19 -> 142.94977 | AB19: =+U19+AA19 -> 253.14977 | AC19: =+W19+T19 -> 611.31 | AD19: =+X19 -> 489.76 | AE19: =+SUM(Z19:AD19)-AB19-AA19 -> 1964.6754 | AG19: 0.005 | AI19: =+Z19 -> 863.60535 | AJ19: =+W19+T19 -> 611.31 | AK19: =+X19 -> 489.76 | AL19: =+AI19+AJ19+AK19-AE19 -> 0
F20: 15 | G20: 414.88 | H20: =+G20*$H$2 -> 435.33358 | I20: =ROUND((($F20)*$L$1*($I$6/100)),2) -> 317.44 | J20: =ROUND(IF($H20<$L$2,0,(($F20)*($H20-$L$2))*($J$6/100)),2) -> 7.45 | K20: =ROUND(IF($H20<$L$2,0,(($F20)*($H20-$L$2))*($K$6/100)),2) -> 20.48 | L20: =ROUND(($H20*($F20)*($L$6/100)),2) -> 16.33 | M20: =ROUND(($H20*($F20)*($M$6/100)),2) -> 45.71 | N20: =ROUND(($H20*($F20)*($N$6/100)),2) -> 24.49 | O20: =ROUND(($H20*($F20)*($O$6/100)),2) -> 68.57 | P20: =ROUND(($H20*($F20)*($AG20)),2) -> 32.65 | Q20: =$H20*($F20)*($Q$6/100) -> 40.812523 | R20: =$H20*($F20)*($R$6/100) -> 114.27507 | S20: =ROUND(($H20*(F20)*($S$6/100)),2) -> 65.3 | T20: =ROUND(($H20*($F20)*($T$6/100)),2) -> 130.6 | U20: =ROUND(($H20*($F20)*($U$6/100)),2) -> 73.46 | V20: =+IFERROR(LOOKUP($G20,$AU$8:$AW$15,$AW$8:$AW$15),0) -> 4.241 | W20: =ROUND(($H20*($F20)*($V$8/100)),2) -> 276.94 | X20: =ROUND(($H20*($F20)*($X$6/100)),2) -> 326.5 | Z20: =+I20+K20+M20+O20+P20+R20+S20 -> 664.42507 | AA20: =+J20+L20+N20+Q20 -> 89.082523 | AB20: =+U20+AA20 -> 162.54252 | AC20: =+W20+T20 -> 407.54 | AD20: =+X20 -> 326.5 | AE20: =+SUM(Z20:AD20)-AB20-AA20 -> 1398.4651 | AG20: 0.005 | AI20: =+Z20 -> 664.42507 | AJ20: =+W20+T20 -> 407.54 | AK20: =+X20 -> 326.5 | AL20: =+AI20+AJ20+AK20-AE20 -> 0
